Workbook

Sheet Data_Mentah
A1: No PO | B1: Tanggal PO | C1: Supplier | D1: Kode Barang | E1: Nama Barang | F1: Kategori | G1: Qty | H1: Harga Satuan | I1: Status PO | J1: Lead Time Janji (hari) | K1: Tanggal Terima Aktual
A2: PO-2024-0001 | B2: 2024-04-01 | C2: PT Indo Chemical | D2: BA701 | E2: Resin Polimer | F2: Bahan Baku | G2: 78 | H2: 500000 | I2: Cancelled | J2: 7
A3: PO-2024-0002 | B3: 2024-03-24 | C3: PT Mega Sparepart | D3: SP954 | E3: Sensor Proximity | F3: Sparepart Mesin | G3: 439 | H3: 500000 | I3: Approved | J3: 14
A4: PO-2024-0003 | B4: 2024-06-18 | C4: CV Anugrah Teknik | D4: CO909 | E4: Masker | F4: Consumables | G4: 357 | H4: 25000 | I4: Received | J4: 7 | K4: 2024-06-23
A5: PO-2024-0004 | B5: 2024-02-20 | C5: CV Anugrah Teknik | D5: SP448 | E5: Bearing 6205 | F5: Sparepart Mesin | G5: 314 | H5: 500000 | I5: Cancelled | J5: 7
A6: PO-2024-0005 | B6: 2024-01-16 | C6: PT Karya Abadi | D6: AT333 | E6: Ballpoint | F6: ATK | G6: 187 | H6: 1200000 | I6: Cancelled | J6: 10
A7: PO-2024-0006 | B7: 2024-04-05 | C7: PT Mega Sparepart | D7: CO187 | E7: Isolasi Kabel | F7: Consumables | G7: 400 | H7: 120000 | I7: Pending | J7: 3
A8: PO-2024-0007 | B8: 2024-02-12 | C8: PT Karya Abadi | D8: SP828 | E8: Gear Reducer | F8: Sparepart Mesin | G8: 406 | H8: 45000 | I8: Approved | J8: 7
A9: PO-2024-0008 | B9: 2024-07-03 | C9: CV Sentosa Jaya | D9: BA415 | E9: Plat Baja 2mm | F9: Bahan Baku | G9: 232 | H9: 250000 | I9: Pending | J9: 3
A10: PO-2024-0009 | B10: 2024-03-08 | C10: CV Sentosa Jaya | D10: SP559 | E10: Gear Reducer | F10: Sparepart Mesin | G10: 290 | H10: 1200000 | I10: Received | J10: 3 | K10: 2024-03-09
A11: PO-2024-0010 | B11: 2024-02-15 | C11: PT Indo Chemical | D11: BA711 | E11: Cat Epoxy | F11: Bahan Kimia | G11: 311 | H11: 250000 | I11: Pending | J11: 3
A12: PO-2024-0011 | B12: 2024-05-29 | C12: CV Anugrah Teknik | D12: AT842 | E12: Kertas A4 | F12: ATK | G12: 466 | H12: 1200000 | I12: Cancelled | J12: 5
A13: PO-2024-0012 | B13: 2024-10-19 | C13: CV Sinar Terang | D13: SP273 | E13: Gear Reducer | F13: Sparepart Mesin | G13: 76 | H13: 120000 | I13: Received | J13: 10 | K13: 2024-10-29
A14: PO-2024-0013 | B14: 2024-02-02 | C14: PT Baja Perkasa | D14: AT531 | E14: Map Folder | F14: ATK | G14: 158 | H14: 850000 | I14: Pending | J14: 7
A15: PO-2024-0014 | B15: 2024-05-08 | C15: CV Mitra Logistik | D15: CO708 | E15: Isolasi Kabel | F15: Consumables | G15: 320 | H15: 75000 | I15: Received | J15: 5 | K15: 2024-05-15
A16: PO-2024-0015 | B16: 2024-01-04 | C16: CV Anugrah Teknik | D16: BA489 | E16: Label Sticker | F16: Bahan Kemasan | G16: 416 | H16: 250000 | I16: Received | J16: 10 | K16: 2024-01-14
A17: PO-2024-0016 | B17: 2024-06-02 | C17: PT Indo Chemical | D17: BA590 | E17: Thinner | F17: Bahan Kimia | G17: 165 | H17: 45000 | I17: Cancelled | J17: 7
A18: PO-2024-0017 | B18: 2024-05-29 | C18: PT Global Packaging | D18: BA433 | E18: Thinner | F18: Bahan Kimia | G18: 197 | H18: 120000 | I18: Pending | J18: 10
A19: PO-2024-0018 | B19: 2024-07-05 | C19: CV Sentosa Jaya | D19: BA706 | E19: Thinner | F19: Bahan Kimia | G19: 284 | H19: 45000 | I19: Approved | J19: 14
A20: PO-2024-0019 | B20: 2024-01-14 | C20: PT Global Packaging | D20: CO548 | E20: Masker | F20: Consumables | G20: 413 | H20: 120000 | I20: Pending | J20: 3
A21: PO-2024-0020 | B21: 2024-07-28 | C21: PT Global Packaging | D21: SP347 | E21: Motor AC 1HP | F21: Sparepart Mesin | G21: 134 | H21: 45000 | I21: Approved | J21: 10
A22: PO-2024-0021 | B22: 2024-02-07 | C22: PT Global Packaging | D22: BA696 | E22: Degreaser | F22: Bahan Kimia | G22: 210 | H22: 1200000 | I22: Received | J22: 10 | K22: 2024-02-23
A23: PO-2024-0022 | B23: 2024-01-19 | C23: PT Indo Chemical | D23: CO708 | E23: Baterai AA | F23: Consumables | G23: 331 | H23: 25000 | I23: Received | J23: 5 | K23: 2024-01-27
A24: PO-2024-0023 | B24: 2024-03-26 | C24: PT Mega Sparepart | D24: BA760 | E24: Kawat Tembaga | F24: Bahan Baku | G24: 351 | H24: 500000 | I24: Cancelled | J24: 7
A25: PO-2024-0024 | B25: 2024-08-08 | C25: CV Sentosa Jaya | D25: BA364 | E25: Plat Baja 2mm | F25: Bahan Baku | G25: 118 | H25: 1200000 | I25: Approved | J25: 14
A26: PO-2024-0025 | B26: 2024-10-24 | C26: PT Mega Sparepart | D26: SP483 | E26: Gear Reducer | F26: Sparepart Mesin | G26: 205 | H26: 850000 | I26: Pending | J26: 14
A27: PO-2024-0026 | B27: 2024-12-19 | C27: CV Sinar Terang | D27: SP125 | E27: Motor AC 1HP | F27: Sparepart Mesin | G27: 252 | H27: 25000 | I27: Received | J27: 3 | K27: 2024-12-21
A28: PO-2024-0027 | B28: 2024-03-13 | C28: PT Indo Chemical | D28: BA566 | E28: Plastik Wrap | F28: Bahan Kemasan | G28: 406 | H28: 75000 | I28: Received | J28: 7 | K28: 2024-03-25
A29: PO-2024-0028 | B29: 2024-02-19 | C29: PT Global Packaging | D29: CO426 | E29: Isolasi Kabel | F29: Consumables | G29: 39 | H29: 120000 | I29: Received | J29: 3 | K29: 2024-02-20
A30: PO-2024-0029 | B30: 2024-06-24 | C30: CV Sentosa Jaya | D30: CO858 | E30: Masker | F30: Consumables | G30: 129 | H30: 1200000 | I30: Received | J30: 5 | K30: 2024-07-02
A31: PO-2024-0030 | B31: 2024-10-13 | C31: CV Anugrah Teknik | D31: AT916 | E31: Tinta Printer | F31: ATK | G31: 212 | H31: 45000 | I31: Received | J31: 10 | K31: 2024-10-27
A32: PO-2024-0031 | B32: 2024-01-15 | C32: PT Mega Sparepart | D32: SP706 | E32: Gear Reducer | F32: Sparepart Mesin | G32: 224 | H32: 500000 | I32: Received | J32: 5 | K32: 2024-01-21
A33: PO-2024-0032 | B33: 2024-05-22 | C33: CV Sentosa Jaya | D33: BA918 | E33: Cat Epoxy | F33: Bahan Kimia | G33: 451 | H33: 1200000 | I33: Received | J33: 7 | K33: 2024-05-30
A34: PO-2024-0033 | B34: 2024-08-22 | C34: CV Sentosa Jaya | D34: BA640 | E34: Lakban Bening | F34: Bahan Kemasan | G34: 499 | H34: 250000 | I34: Approved | J34: 14
A35: PO-2024-0034 | B35: 2024-07-19 | C35: PT Mega Sparepart | D35: BA460 | E35: Kain Katun Roll | F35: Bahan Baku | G35: 437 | H35: 850000 | I35: Approved | J35: 7
A36: PO-2024-0035 | B36: 2024-11-10 | C36: PT Mega Sparepart | D36: BA420 | E36: Resin Polimer | F36: Bahan Baku | G36: 65 | H36: 75000 | I36: Received | J36: 5 | K36: 2024-11-18
A37: PO-2024-0036 | B37: 2024-12-21 | C37: PT Baja Perkasa | D37: BA528 | E37: Degreaser | F37: Bahan Kimia | G37: 310 | H37: 45000 | I37: Approved | J37: 10
A38: PO-2024-0037 | B38: 2024-04-05 | C38: PT Global Packaging | D38: CO810 | E38: Baterai AA | F38: Consumables | G38: 475 | H38: 45000 | I38: Approved | J38: 10
A39: PO-2024-0038 | B39: 2024-05-27 | C39: PT Baja Perkasa | D39: SP962 | E39: Motor AC 1HP | F39: Sparepart Mesin | G39: 235 | H39: 15000 | I39: Pending | J39: 3
A40: PO-2024-0039 | B40: 2024-09-05 | C40: PT Baja Perkasa | D40: SP675 | E40: Gear Reducer | F40: Sparepart Mesin | G40: 263 | H40: 850000 | I40: Received | J40: 10 | K40: 2024-09-19
...

Sheet Latihan_Isi_Sendiri
A1: No PO | B1: Tanggal PO | C1: Supplier | D1: Kode Barang | E1: Nama Barang | F1: Kategori | G1: Qty | H1: Harga Satuan | I1: Status PO | J1: Lead Time Janji (hari) | K1: Tanggal Terima Aktual | L1: Total Harga (Qty x Harga) | M1: Keterlambatan (hari) | N1: Status Ketepatan Kirim
A2: PO-2024-0001 | B2: 2024-04-01 | C2: PT Indo Chemical | D2: BA701 | E2: Resin Polimer | F2: Bahan Baku | G2: 78 | H2: 500000 | I2: Cancelled | J2: 7 | L2: =G2*H2 -> 39000000 | M2: =IF(I2="Received",(K2-B2)-J2,"-") -> - | N2: =IF(I2="Received",IF(L2<=0,"Tepat Waktu","Terlambat"),"-") -> -
A3: PO-2024-0002 | B3: 2024-03-24 | C3: PT Mega Sparepart | D3: SP954 | E3: Sensor Proximity | F3: Sparepart Mesin | G3: 439 | H3: 500000 | I3: Approved | J3: 14
A4: PO-2024-0003 | B4: 2024-06-18 | C4: CV Anugrah Teknik | D4: CO909 | E4: Masker | F4: Consumables | G4: 357 | H4: 25000 | I4: Received | J4: 7 | K4: 2024-06-23
A5: PO-2024-0004 | B5: 2024-02-20 | C5: CV Anugrah Teknik | D5: SP448 | E5: Bearing 6205 | F5: Sparepart Mesin | G5: 314 | H5: 500000 | I5: Cancelled | J5: 7
A6: PO-2024-0005 | B6: 2024-01-16 | C6: PT Karya Abadi | D6: AT333 | E6: Ballpoint | F6: ATK | G6: 187 | H6: 1200000 | I6: Cancelled | J6: 10
A7: PO-2024-0006 | B7: 2024-04-05 | C7: PT Mega Sparepart | D7: CO187 | E7: Isolasi Kabel | F7: Consumables | G7: 400 | H7: 120000 | I7: Pending | J7: 3
A8: PO-2024-0007 | B8: 2024-02-12 | C8: PT Karya Abadi | D8: SP828 | E8: Gear Reducer | F8: Sparepart Mesin | G8: 406 | H8: 45000 | I8: Approved | J8: 7
A9: PO-2024-0008 | B9: 2024-07-03 | C9: CV Sentosa Jaya | D9: BA415 | E9: Plat Baja 2mm | F9: Bahan Baku | G9: 232 | H9: 250000 | I9: Pending | J9: 3
A10: PO-2024-0009 | B10: 2024-03-08 | C10: CV Sentosa Jaya | D10: SP559 | E10: Gear Reducer | F10: Sparepart Mesin | G10: 290 | H10: 1200000 | I10: Received | J10: 3 | K10: 2024-03-09
A11: PO-2024-0010 | B11: 2024-02-15 | C11: PT Indo Chemical | D11: BA711 | E11: Cat Epoxy | F11: Bahan Kimia | G11: 311 | H11: 250000 | I11: Pending | J11: 3
A12: PO-2024-0011 | B12: 2024-05-29 | C12: CV Anugrah Teknik | D12: AT842 | E12: Kertas A4 | F12: ATK | G12: 466 | H12: 1200000 | I12: Cancelled | J12: 5
A13: PO-2024-0012 | B13: 2024-10-19 | C13: CV Sinar Terang | D13: SP273 | E13: Gear Reducer | F13: Sparepart Mesin | G13: 76 | H13: 120000 | I13: Received | J13: 10 | K13: 2024-10-29
A14: PO-2024-0013 | B14: 2024-02-02 | C14: PT Baja Perkasa | D14: AT531 | E14: Map Folder | F14: ATK | G14: 158 | H14: 850000 | I14: Pending | J14: 7
A15: PO-2024-0014 | B15: 2024-05-08 | C15: CV Mitra Logistik | D15: CO708 | E15: Isolasi Kabel | F15: Consumables | G15: 320 | H15: 75000 | I15: Received | J15: 5 | K15: 2024-05-15
A16: PO-2024-0015 | B16: 2024-01-04 | C16: CV Anugrah Teknik | D16: BA489 | E16: Label Sticker | F16: Bahan Kemasan | G16: 416 | H16: 250000 | I16: Received | J16: 10 | K16: 2024-01-14
A17: PO-2024-0016 | B17: 2024-06-02 | C17: PT Indo Chemical | D17: BA590 | E17: Thinner | F17: Bahan Kimia | G17: 165 | H17: 45000 | I17: Cancelled | J17: 7
A18: PO-2024-0017 | B18: 2024-05-29 | C18: PT Global Packaging | D18: BA433 | E18: Thinner | F18: Bahan Kimia | G18: 197 | H18: 120000 | I18: Pending | J18: 10
A19: PO-2024-0018 | B19: 2024-07-05 | C19: CV Sentosa Jaya | D19: BA706 | E19: Thinner | F19: Bahan Kimia | G19: 284 | H19: 45000 | I19: Approved | J19: 14
A20: PO-2024-0019 | B20: 2024-01-14 | C20: PT Global Packaging | D20: CO548 | E20: Masker | F20: Consumables | G20: 413 | H20: 120000 | I20: Pending | J20: 3
A21: PO-2024-0020 | B21: 2024-07-28 | C21: PT Global Packaging | D21: SP347 | E21: Motor AC 1HP | F21: Sparepart Mesin | G21: 134 | H21: 45000 | I21: Approved | J21: 10
A22: PO-2024-0021 | B22: 2024-02-07 | C22: PT Global Packaging | D22: BA696 | E22: Degreaser | F22: Bahan Kimia | G22: 210 | H22: 1200000 | I22: Received | J22: 10 | K22: 2024-02-23
A23: PO-2024-0022 | B23: 2024-01-19 | C23: PT Indo Chemical | D23: CO708 | E23: Baterai AA | F23: Consumables | G23: 331 | H23: 25000 | I23: Received | J23: 5 | K23: 2024-01-27
A24: PO-2024-0023 | B24: 2024-03-26 | C24: PT Mega Sparepart | D24: BA760 | E24: Kawat Tembaga | F24: Bahan Baku | G24: 351 | H24: 500000 | I24: Cancelled | J24: 7
A25: PO-2024-0024 | B25: 2024-08-08 | C25: CV Sentosa Jaya | D25: BA364 | E25: Plat Baja 2mm | F25: Bahan Baku | G25: 118 | H25: 1200000 | I25: Approved | J25: 14
A26: PO-2024-0025 | B26: 2024-10-24 | C26: PT Mega Sparepart | D26: SP483 | E26: Gear Reducer | F26: Sparepart Mesin | G26: 205 | H26: 850000 | I26: Pending | J26: 14
A27: PO-2024-0026 | B27: 2024-12-19 | C27: CV Sinar Terang | D27: SP125 | E27: Motor AC 1HP | F27: Sparepart Mesin | G27: 252 | H27: 25000 | I27: Received | J27: 3 | K27: 2024-12-21
A28: PO-2024-0027 | B28: 2024-03-13 | C28: PT Indo Chemical | D28: BA566 | E28: Plastik Wrap | F28: Bahan Kemasan | G28: 406 | H28: 75000 | I28: Received | J28: 7 | K28: 2024-03-25
A29: PO-2024-0028 | B29: 2024-02-19 | C29: PT Global Packaging | D29: CO426 | E29: Isolasi Kabel | F29: Consumables | G29: 39 | H29: 120000 | I29: Received | J29: 3 | K29: 2024-02-20
A30: PO-2024-0029 | B30: 2024-06-24 | C30: CV Sentosa Jaya | D30: CO858 | E30: Masker | F30: Consumables | G30: 129 | H30: 1200000 | I30: Received | J30: 5 | K30: 2024-07-02
A31: PO-2024-0030 | B31: 2024-10-13 | C31: CV Anugrah Teknik | D31: AT916 | E31: Tinta Printer | F31: ATK | G31: 212 | H31: 45000 | I31: Received | J31: 10 | K31: 2024-10-27
A32: PO-2024-0031 | B32: 2024-01-15 | C32: PT Mega Sparepart | D32: SP706 | E32: Gear Reducer | F32: Sparepart Mesin | G32: 224 | H32: 500000 | I32: Received | J32: 5 | K32: 2024-01-21
A33: PO-2024-0032 | B33: 2024-05-22 | C33: CV Sentosa Jaya | D33: BA918 | E33: Cat Epoxy | F33: Bahan Kimia | G33: 451 | H33: 1200000 | I33: Received | J33: 7 | K33: 2024-05-30
A34: PO-2024-0033 | B34: 2024-08-22 | C34: CV Sentosa Jaya | D34: BA640 | E34: Lakban Bening | F34: Bahan Kemasan | G34: 499 | H34: 250000 | I34: Approved | J34: 14
A35: PO-2024-0034 | B35: 2024-07-19 | C35: PT Mega Sparepart | D35: BA460 | E35: Kain Katun Roll | F35: Bahan Baku | G35: 437 | H35: 850000 | I35: Approved | J35: 7
A36: PO-2024-0035 | B36: 2024-11-10 | C36: PT Mega Sparepart | D36: BA420 | E36: Resin Polimer | F36: Bahan Baku | G36: 65 | H36: 75000 | I36: Received | J36: 5 | K36: 2024-11-18
A37: PO-2024-0036 | B37: 2024-12-21 | C37: PT Baja Perkasa | D37: BA528 | E37: Degreaser | F37: Bahan Kimia | G37: 310 | H37: 45000 | I37: Approved | J37: 10
A38: PO-2024-0037 | B38: 2024-04-05 | C38: PT Global Packaging | D38: CO810 | E38: Baterai AA | F38: Consumables | G38: 475 | H38: 45000 | I38: Approved | J38: 10
A39: PO-2024-0038 | B39: 2024-05-27 | C39: PT Baja Perkasa | D39: SP962 | E39: Motor AC 1HP | F39: Sparepart Mesin | G39: 235 | H39: 15000 | I39: Pending | J39: 3
A40: PO-2024-0039 | B40: 2024-09-05 | C40: PT Baja Perkasa | D40: SP675 | E40: Gear Reducer | F40: Sparepart Mesin | G40: 263 | H40: 850000 | I40: Received | J40: 10 | K40: 2024-09-19
...

Sheet Kunci_Jawaban
A1: No PO | B1: Tanggal PO | C1: Supplier | D1: Kode Barang | E1: Nama Barang | F1: Kategori | G1: Qty | H1: Harga Satuan | I1: Status PO | J1: Lead Time Janji (hari) | K1: Tanggal Terima Aktual | L1: Total Harga (Qty x Harga) | M1: Keterlambatan (hari) | N1: Status Ketepatan Kirim
A2: PO-2024-0001 | B2: 2024-04-01 | C2: PT Indo Chemical | D2: BA701 | E2: Resin Polimer | F2: Bahan Baku | G2: 78 | H2: 500000 | I2: Cancelled | J2: 7 | L2: =G2*H2 -> 39000000 | M2: =IF(I2="Received",(K2-B2)-J2,"-") -> - | N2: =IF(I2="Received",IF(M2<=0,"Tepat Waktu","Terlambat"),"-") -> -
A3: PO-2024-0002 | B3: 2024-03-24 | C3: PT Mega Sparepart | D3: SP954 | E3: Sensor Proximity | F3: Sparepart Mesin | G3: 439 | H3: 500000 | I3: Approved | J3: 14 | L3: =G3*H3 -> 219500000 | M3: =IF(I3="Received",(K3-B3)-J3,"-") -> - | N3: =IF(I3="Received",IF(M3<=0,"Tepat Waktu","Terlambat"),"-") -> -
A4: PO-2024-0003 | B4: 2024-06-18 | C4: CV Anugrah Teknik | D4: CO909 | E4: Masker | F4: Consumables | G4: 357 | H4: 25000 | I4: Received | J4: 7 | K4: 2024-06-23 | L4: =G4*H4 -> 8925000 | M4: =IF(I4="Received",(K4-B4)-J4,"-") -> -2 | N4: =IF(I4="Received",IF(M4<=0,"Tepat Waktu","Terlambat"),"-") -> Tepat Waktu
A5: PO-2024-0004 | B5: 2024-02-20 | C5: CV Anugrah Teknik | D5: SP448 | E5: Bearing 6205 | F5: Sparepart Mesin | G5: 314 | H5: 500000 | I5: Cancelled | J5: 7 | L5: =G5*H5 -> 157000000 | M5: =IF(I5="Received",(K5-B5)-J5,"-") -> - | N5: =IF(I5="Received",IF(M5<=0,"Tepat Waktu","Terlambat"),"-") -> -
A6: PO-2024-0005 | B6: 2024-01-16 | C6: PT Karya Abadi | D6: AT333 | E6: Ballpoint | F6: ATK | G6: 187 | H6: 1200000 | I6: Cancelled | J6: 10 | L6: =G6*H6 -> 224400000 | M6: =IF(I6="Received",(K6-B6)-J6,"-") -> - | N6: =IF(I6="Received",IF(M6<=0,"Tepat Waktu","Terlambat"),"-") -> -
A7: PO-2024-0006 | B7: 2024-04-05 | C7: PT Mega Sparepart | D7: CO187 | E7: Isolasi Kabel | F7: Consumables | G7: 400 | H7: 120000 | I7: Pending | J7: 3 | L7: =G7*H7 -> 48000000 | M7: =IF(I7="Received",(K7-B7)-J7,"-") -> - | N7: =IF(I7="Received",IF(M7<=0,"Tepat Waktu","Terlambat"),"-") -> -
A8: PO-2024-0007 | B8: 2024-02-12 | C8: PT Karya Abadi | D8: SP828 | E8: Gear Reducer | F8: Sparepart Mesin | G8: 406 | H8: 45000 | I8: Approved | J8: 7 | L8: =G8*H8 -> 18270000 | M8: =IF(I8="Received",(K8-B8)-J8,"-") -> - | N8: =IF(I8="Received",IF(M8<=0,"Tepat Waktu","Terlambat"),"-") -> -
A9: PO-2024-0008 | B9: 2024-07-03 | C9: CV Sentosa Jaya | D9: BA415 | E9: Plat Baja 2mm | F9: Bahan Baku | G9: 232 | H9: 250000 | I9: Pending | J9: 3 | L9: =G9*H9 -> 58000000 | M9: =IF(I9="Received",(K9-B9)-J9,"-") -> - | N9: =IF(I9="Received",IF(M9<=0,"Tepat Waktu","Terlambat"),"-") -> -
A10: PO-2024-0009 | B10: 2024-03-08 | C10: CV Sentosa Jaya | D10: SP559 | E10: Gear Reducer | F10: Sparepart Mesin | G10: 290 | H10: 1200000 | I10: Received | J10: 3 | K10: 2024-03-09 | L10: =G10*H10 -> 348000000 | M10: =IF(I10="Received",(K10-B10)-J10,"-") -> -2 | N10: =IF(I10="Received",IF(M10<=0,"Tepat Waktu","Terlambat"),"-") -> Tepat Waktu
A11: PO-2024-0010 | B11: 2024-02-15 | C11: PT Indo Chemical | D11: BA711 | E11: Cat Epoxy | F11: Bahan Kimia | G11: 311 | H11: 250000 | I11: Pending | J11: 3 | L11: =G11*H11 -> 77750000 | M11: =IF(I11="Received",(K11-B11)-J11,"-") -> - | N11: =IF(I11="Received",IF(M11<=0,"Tepat Waktu","Terlambat"),"-") -> -
A12: PO-2024-0011 | B12: 2024-05-29 | C12: CV Anugrah Teknik | D12: AT842 | E12: Kertas A4 | F12: ATK | G12: 466 | H12: 1200000 | I12: Cancelled | J12: 5 | L12: =G12*H12 -> 559200000 | M12: =IF(I12="Received",(K12-B12)-J12,"-") -> - | N12: =IF(I12="Received",IF(M12<=0,"Tepat Waktu","Terlambat"),"-") -> -
A13: PO-2024-0012 | B13: 2024-10-19 | C13: CV Sinar Terang | D13: SP273 | E13: Gear Reducer | F13: Sparepart Mesin | G13: 76 | H13: 120000 | I13: Received | J13: 10 | K13: 2024-10-29 | L13: =G13*H13 -> 9120000 | M13: =IF(I13="Received",(K13-B13)-J13,"-") -> 0 | N13: =IF(I13="Received",IF(M13<=0,"Tepat Waktu","Terlambat"),"-") -> Tepat Waktu
A14: PO-2024-0013 | B14: 2024-02-02 | C14: PT Baja Perkasa | D14: AT531 | E14: Map Folder | F14: ATK | G14: 158 | H14: 850000 | I14: Pending | J14: 7 | L14: =G14*H14 -> 134300000 | M14: =IF(I14="Received",(K14-B14)-J14,"-") -> - | N14: =IF(I14="Received",IF(M14<=0,"Tepat Waktu","Terlambat"),"-") -> -
A15: PO-2024-0014 | B15: 2024-05-08 | C15: CV Mitra Logistik | D15: CO708 | E15: Isolasi Kabel | F15: Consumables | G15: 320 | H15: 75000 | I15: Received | J15: 5 | K15: 2024-05-15 | L15: =G15*H15 -> 24000000 | M15: =IF(I15="Received",(K15-B15)-J15,"-") -> 2 | N15: =IF(I15="Received",IF(M15<=0,"Tepat Waktu","Terlambat"),"-") -> Terlambat
A16: PO-2024-0015 | B16: 2024-01-04 | C16: CV Anugrah Teknik | D16: BA489 | E16: Label Sticker | F16: Bahan Kemasan | G16: 416 | H16: 250000 | I16: Received | J16: 10 | K16: 2024-01-14 | L16: =G16*H16 -> 104000000 | M16: =IF(I16="Received",(K16-B16)-J16,"-") -> 0 | N16: =IF(I16="Received",IF(M16<=0,"Tepat Waktu","Terlambat"),"-") -> Tepat Waktu
A17: PO-2024-0016 | B17: 2024-06-02 | C17: PT Indo Chemical | D17: BA590 | E17: Thinner | F17: Bahan Kimia | G17: 165 | H17: 45000 | I17: Cancelled | J17: 7 | L17: =G17*H17 -> 7425000 | M17: =IF(I17="Received",(K17-B17)-J17,"-") -> - | N17: =IF(I17="Received",IF(M17<=0,"Tepat Waktu","Terlambat"),"-") -> -
A18: PO-2024-0017 | B18: 2024-05-29 | C18: PT Global Packaging | D18: BA433 | E18: Thinner | F18: Bahan Kimia | G18: 197 | H18: 120000 | I18: Pending | J18: 10 | L18: =G18*H18 -> 23640000 | M18: =IF(I18="Received",(K18-B18)-J18,"-") -> - | N18: =IF(I18="Received",IF(M18<=0,"Tepat Waktu","Terlambat"),"-") -> -
A19: PO-2024-0018 | B19: 2024-07-05 | C19: CV Sentosa Jaya | D19: BA706 | E19: Thinner | F19: Bahan Kimia | G19: 284 | H19: 45000 | I19: Approved | J19: 14 | L19: =G19*H19 -> 12780000 | M19: =IF(I19="Received",(K19-B19)-J19,"-") -> - | N19: =IF(I19="Received",IF(M19<=0,"Tepat Waktu","Terlambat"),"-") -> -
A20: PO-2024-0019 | B20: 2024-01-14 | C20: PT Global Packaging | D20: CO548 | E20: Masker | F20: Consumables | G20: 413 | H20: 120000 | I20: Pending | J20: 3 | L20: =G20*H20 -> 49560000 | M20: =IF(I20="Received",(K20-B20)-J20,"-") -> - | N20: =IF(I20="Received",IF(M20<=0,"Tepat Waktu","Terlambat"),"-") -> -
A21: PO-2024-0020 | B21: 2024-07-28 | C21: PT Global Packaging | D21: SP347 | E21: Motor AC 1HP | F21: Sparepart Mesin | G21: 134 | H21: 45000 | I21: Approved | J21: 10 | L21: =G21*H21 -> 6030000 | M21: =IF(I21="Received",(K21-B21)-J21,"-") -> - | N21: =IF(I21="Received",IF(M21<=0,"Tepat Waktu","Terlambat"),"-") -> -
A22: PO-2024-0021 | B22: 2024-02-07 | C22: PT Global Packaging | D22: BA696 | E22: Degreaser | F22: Bahan Kimia | G22: 210 | H22: 1200000 | I22: Received | J22: 10 | K22: 2024-02-23 | L22: =G22*H22 -> 252000000 | M22: =IF(I22="Received",(K22-B22)-J22,"-") -> 6 | N22: =IF(I22="Received",IF(M22<=0,"Tepat Waktu","Terlambat"),"-") -> Terlambat
A23: PO-2024-0022 | B23: 2024-01-19 | C23: PT Indo Chemical | D23: CO708 | E23: Baterai AA | F23: Consumables | G23: 331 | H23: 25000 | I23: Received | J23: 5 | K23: 2024-01-27 | L23: =G23*H23 -> 8275000 | M23: =IF(I23="Received",(K23-B23)-J23,"-") -> 3 | N23: =IF(I23="Received",IF(M23<=0,"Tepat Waktu","Terlambat"),"-") -> Terlambat
A24: PO-2024-0023 | B24: 2024-03-26 | C24: PT Mega Sparepart | D24: BA760 | E24: Kawat Tembaga | F24: Bahan Baku | G24: 351 | H24: 500000 | I24: Cancelled | J24: 7 | L24: =G24*H24 -> 175500000 | M24: =IF(I24="Received",(K24-B24)-J24,"-") -> - | N24: =IF(I24="Received",IF(M24<=0,"Tepat Waktu","Terlambat"),"-") -> -
A25: PO-2024-0024 | B25: 2024-08-08 | C25: CV Sentosa Jaya | D25: BA364 | E25: Plat Baja 2mm | F25: Bahan Baku | G25: 118 | H25: 1200000 | I25: Approved | J25: 14 | L25: =G25*H25 -> 141600000 | M25: =IF(I25="Received",(K25-B25)-J25,"-") -> - | N25: =IF(I25="Received",IF(M25<=0,"Tepat Waktu","Terlambat"),"-") -> -
A26: PO-2024-0025 | B26: 2024-10-24 | C26: PT Mega Sparepart | D26: SP483 | E26: Gear Reducer | F26: Sparepart Mesin | G26: 205 | H26: 850000 | I26: Pending | J26: 14 | L26: =G26*H26 -> 174250000 | M26: =IF(I26="Received",(K26-B26)-J26,"-") -> - | N26: =IF(I26="Received",IF(M26<=0,"Tepat Waktu","Terlambat"),"-") -> -
A27: PO-2024-0026 | B27: 2024-12-19 | C27: CV Sinar Terang | D27: SP125 | E27: Motor AC 1HP | F27: Sparepart Mesin | G27: 252 | H27: 25000 | I27: Received | J27: 3 | K27: 2024-12-21 | L27: =G27*H27 -> 6300000 | M27: =IF(I27="Received",(K27-B27)-J27,"-") -> -1 | N27: =IF(I27="Received",IF(M27<=0,"Tepat Waktu","Terlambat"),"-") -> Tepat Waktu
A28: PO-2024-0027 | B28: 2024-03-13 | C28: PT Indo Chemical | D28: BA566 | E28: Plastik Wrap | F28: Bahan Kemasan | G28: 406 | H28: 75000 | I28: Received | J28: 7 | K28: 2024-03-25 | L28: =G28*H28 -> 30450000 | M28: =IF(I28="Received",(K28-B28)-J28,"-") -> 5 | N28: =IF(I28="Received",IF(M28<=0,"Tepat Waktu","Terlambat"),"-") -> Terlambat
A29: PO-2024-0028 | B29: 2024-02-19 | C29: PT Global Packaging | D29: CO426 | E29: Isolasi Kabel | F29: Consumables | G29: 39 | H29: 120000 | I29: Received | J29: 3 | K29: 2024-02-20 | L29: =G29*H29 -> 4680000 | M29: =IF(I29="Received",(K29-B29)-J29,"-") -> -2 | N29: =IF(I29="Received",IF(M29<=0,"Tepat Waktu","Terlambat"),"-") -> Tepat Waktu
A30: PO-2024-0029 | B30: 2024-06-24 | C30: CV Sentosa Jaya | D30: CO858 | E30: Masker | F30: Consumables | G30: 129 | H30: 1200000 | I30: Received | J30: 5 | K30: 2024-07-02 | L30: =G30*H30 -> 154800000 | M30: =IF(I30="Received",(K30-B30)-J30,"-") -> 3 | N30: =IF(I30="Received",IF(M30<=0,"Tepat Waktu","Terlambat"),"-") -> Terlambat
A31: PO-2024-0030 | B31: 2024-10-13 | C31: CV Anugrah Teknik | D31: AT916 | E31: Tinta Printer | F31: ATK | G31: 212 | H31: 45000 | I31: Received | J31: 10 | K31: 2024-10-27 | L31: =G31*H31 -> 9540000 | M31: =IF(I31="Received",(K31-B31)-J31,"-") -> 4 | N31: =IF(I31="Received",IF(M31<=0,"Tepat Waktu","Terlambat"),"-") -> Terlambat
A32: PO-2024-0031 | B32: 2024-01-15 | C32: PT Mega Sparepart | D32: SP706 | E32: Gear Reducer | F32: Sparepart Mesin | G32: 224 | H32: 500000 | I32: Received | J32: 5 | K32: 2024-01-21 | L32: =G32*H32 -> 112000000 | M32: =IF(I32="Received",(K32-B32)-J32,"-") -> 1 | N32: =IF(I32="Received",IF(M32<=0,"Tepat Waktu","Terlambat"),"-") -> Terlambat
A33: PO-2024-0032 | B33: 2024-05-22 | C33: CV Sentosa Jaya | D33: BA918 | E33: Cat Epoxy | F33: Bahan Kimia | G33: 451 | H33: 1200000 | I33: Received | J33: 7 | K33: 2024-05-30 | L33: =G33*H33 -> 541200000 | M33: =IF(I33="Received",(K33-B33)-J33,"-") -> 1 | N33: =IF(I33="Received",IF(M33<=0,"Tepat Waktu","Terlambat"),"-") -> Terlambat
A34: PO-2024-0033 | B34: 2024-08-22 | C34: CV Sentosa Jaya | D34: BA640 | E34: Lakban Bening | F34: Bahan Kemasan | G34: 499 | H34: 250000 | I34: Approved | J34: 14 | L34: =G34*H34 -> 124750000 | M34: =IF(I34="Received",(K34-B34)-J34,"-") -> - | N34: =IF(I34="Received",IF(M34<=0,"Tepat Waktu","Terlambat"),"-") -> -
A35: PO-2024-0034 | B35: 2024-07-19 | C35: PT Mega Sparepart | D35: BA460 | E35: Kain Katun Roll | F35: Bahan Baku | G35: 437 | H35: 850000 | I35: Approved | J35: 7 | L35: =G35*H35 -> 371450000 | M35: =IF(I35="Received",(K35-B35)-J35,"-") -> - | N35: =IF(I35="Received",IF(M35<=0,"Tepat Waktu","Terlambat"),"-") -> -
A36: PO-2024-0035 | B36: 2024-11-10 | C36: PT Mega Sparepart | D36: BA420 | E36: Resin Polimer | F36: Bahan Baku | G36: 65 | H36: 75000 | I36: Received | J36: 5 | K36: 2024-11-18 | L36: =G36*H36 -> 4875000 | M36: =IF(I36="Received",(K36-B36)-J36,"-") -> 3 | N36: =IF(I36="Received",IF(M36<=0,"Tepat Waktu","Terlambat"),"-") -> Terlambat
A37: PO-2024-0036 | B37: 2024-12-21 | C37: PT Baja Perkasa | D37: BA528 | E37: Degreaser | F37: Bahan Kimia | G37: 310 | H37: 45000 | I37: Approved | J37: 10 | L37: =G37*H37 -> 13950000 | M37: =IF(I37="Received",(K37-B37)-J37,"-") -> - | N37: =IF(I37="Received",IF(M37<=0,"Tepat Waktu","Terlambat"),"-") -> -
A38: PO-2024-0037 | B38: 2024-04-05 | C38: PT Global Packaging | D38: CO810 | E38: Baterai AA | F38: Consumables | G38: 475 | H38: 45000 | I38: Approved | J38: 10 | L38: =G38*H38 -> 21375000 | M38: =IF(I38="Received",(K38-B38)-J38,"-") -> - | N38: =IF(I38="Received",IF(M38<=0,"Tepat Waktu","Terlambat"),"-") -> -
A39: PO-2024-0038 | B39: 2024-05-27 | C39: PT Baja Perkasa | D39: SP962 | E39: Motor AC 1HP | F39: Sparepart Mesin | G39: 235 | H39: 15000 | I39: Pending | J39: 3 | L39: =G39*H39 -> 3525000 | M39: =IF(I39="Received",(K39-B39)-J39,"-") -> - | N39: =IF(I39="Received",IF(M39<=0,"Tepat Waktu","Terlambat"),"-") -> -
A40: PO-2024-0039 | B40: 2024-09-05 | C40: PT Baja Perkasa | D40: SP675 | E40: Gear Reducer | F40: Sparepart Mesin | G40: 263 | H40: 850000 | I40: Received | J40: 10 | K40: 2024-09-19 | L40: =G40*H40 -> 223550000 | M40: =IF(I40="Received",(K40-B40)-J40,"-") -> 4 | N40: =IF(I40="Received",IF(M40<=0,"Tepat Waktu","Terlambat"),"-") -> Terlambat
...

Sheet Rekap_Ringkasan
A1: REKAP PURCHASING - PT MAJUJAYA MANUFAKTUR
A2: Sumber data: sheet Kunci_Jawaban
A4: Supplier | B4: Jumlah PO | C4: Total Nilai Pembelian | D4: Rata-rata Lead Time Janji (hari) | E4: Jml PO Received | F4: Jml Tepat Waktu | G4: % Ketepatan Kirim | H4: Ranking Nilai Pembelian
A5: CV Anugrah Teknik | B5: =COUNTIF(Kunci_Jawaban!C:C,A5) -> 25 | C5: =SUMIF(Kunci_Jawaban!C:C,A5,Kunci_Jawaban!L:L) -> 2162295000 | D5: =AVERAGEIF(Kunci_Jawaban!C:C,A5,Kunci_Jawaban!J:J) -> 7.88 | E5: =COUNTIFS(Kunci_Jawaban!C:C,A5,Kunci_Jawaban!I:I,"Received") -> 14 | F5: =COUNTIFS(Kunci_Jawaban!C:C,A5,Kunci_Jawaban!N:N,"Tepat Waktu") -> 3 | G5: =IFERROR(F5/E5*100,0) -> 21.428571 | H5: =RANK(C5,$C$5:$C$14) -> 5
A6: CV Mitra Logistik | B6: =COUNTIF(Kunci_Jawaban!C:C,A6) -> 17 | C6: =SUMIF(Kunci_Jawaban!C:C,A6,Kunci_Jawaban!L:L) -> 902815000 | D6: =AVERAGEIF(Kunci_Jawaban!C:C,A6,Kunci_Jawaban!J:J) -> 7.1176471 | E6: =COUNTIFS(Kunci_Jawaban!C:C,A6,Kunci_Jawaban!I:I,"Received") -> 12 | F6: =COUNTIFS(Kunci_Jawaban!C:C,A6,Kunci_Jawaban!N:N,"Tepat Waktu") -> 5 | G6: =IFERROR(F6/E6*100,0) -> 41.666667 | H6: =RANK(C6,$C$5:$C$14) -> 9
A7: CV Sentosa Jaya | B7: =COUNTIF(Kunci_Jawaban!C:C,A7) -> 27 | C7: =SUMIF(Kunci_Jawaban!C:C,A7,Kunci_Jawaban!L:L) -> 3052380000 | D7: =AVERAGEIF(Kunci_Jawaban!C:C,A7,Kunci_Jawaban!J:J) -> 7 | E7: =COUNTIFS(Kunci_Jawaban!C:C,A7,Kunci_Jawaban!I:I,"Received") -> 15 | F7: =COUNTIFS(Kunci_Jawaban!C:C,A7,Kunci_Jawaban!N:N,"Tepat Waktu") -> 2 | G7: =IFERROR(F7/E7*100,0) -> 13.333333 | H7: =RANK(C7,$C$5:$C$14) -> 2
A8: CV Sinar Terang | B8: =COUNTIF(Kunci_Jawaban!C:C,A8) -> 24 | C8: =SUMIF(Kunci_Jawaban!C:C,A8,Kunci_Jawaban!L:L) -> 1198325000 | D8: =AVERAGEIF(Kunci_Jawaban!C:C,A8,Kunci_Jawaban!J:J) -> 8.0416667 | E8: =COUNTIFS(Kunci_Jawaban!C:C,A8,Kunci_Jawaban!I:I,"Received") -> 13 | F8: =COUNTIFS(Kunci_Jawaban!C:C,A8,Kunci_Jawaban!N:N,"Tepat Waktu") -> 5 | G8: =IFERROR(F8/E8*100,0) -> 38.461538 | H8: =RANK(C8,$C$5:$C$14) -> 8
A9: PT Baja Perkasa | B9: =COUNTIF(Kunci_Jawaban!C:C,A9) -> 24 | C9: =SUMIF(Kunci_Jawaban!C:C,A9,Kunci_Jawaban!L:L) -> 2390670000 | D9: =AVERAGEIF(Kunci_Jawaban!C:C,A9,Kunci_Jawaban!J:J) -> 7.7083333 | E9: =COUNTIFS(Kunci_Jawaban!C:C,A9,Kunci_Jawaban!I:I,"Received") -> 14 | F9: =COUNTIFS(Kunci_Jawaban!C:C,A9,Kunci_Jawaban!N:N,"Tepat Waktu") -> 6 | G9: =IFERROR(F9/E9*100,0) -> 42.857143 | H9: =RANK(C9,$C$5:$C$14) -> 3
A10: PT Global Packaging | B10: =COUNTIF(Kunci_Jawaban!C:C,A10) -> 26 | C10: =SUMIF(Kunci_Jawaban!C:C,A10,Kunci_Jawaban!L:L) -> 3054885000 | D10: =AVERAGEIF(Kunci_Jawaban!C:C,A10,Kunci_Jawaban!J:J) -> 8.1538462 | E10: =COUNTIFS(Kunci_Jawaban!C:C,A10,Kunci_Jawaban!I:I,"Received") -> 10 | F10: =COUNTIFS(Kunci_Jawaban!C:C,A10,Kunci_Jawaban!N:N,"Tepat Waktu") -> 1 | G10: =IFERROR(F10/E10*100,0) -> 10 | H10: =RANK(C10,$C$5:$C$14) -> 1
A11: PT Indo Chemical | B11: =COUNTIF(Kunci_Jawaban!C:C,A11) -> 25 | C11: =SUMIF(Kunci_Jawaban!C:C,A11,Kunci_Jawaban!L:L) -> 885135000 | D11: =AVERAGEIF(Kunci_Jawaban!C:C,A11,Kunci_Jawaban!J:J) -> 7.88 | E11: =COUNTIFS(Kunci_Jawaban!C:C,A11,Kunci_Jawaban!I:I,"Received") -> 11 | F11: =COUNTIFS(Kunci_Jawaban!C:C,A11,Kunci_Jawaban!N:N,"Tepat Waktu") -> 5 | G11: =IFERROR(F11/E11*100,0) -> 45.454545 | H11: =RANK(C11,$C$5:$C$14) -> 10
A12: PT Karya Abadi | B12: =COUNTIF(Kunci_Jawaban!C:C,A12) -> 18 | C12: =SUMIF(Kunci_Jawaban!C:C,A12,Kunci_Jawaban!L:L) -> 1420600000 | D12: =AVERAGEIF(Kunci_Jawaban!C:C,A12,Kunci_Jawaban!J:J) -> 7.6666667 | E12: =COUNTIFS(Kunci_Jawaban!C:C,A12,Kunci_Jawaban!I:I,"Received") -> 4 | F12: =COUNTIFS(Kunci_Jawaban!C:C,A12,Kunci_Jawaban!N:N,"Tepat Waktu") -> 2 | G12: =IFERROR(F12/E12*100,0) -> 50 | H12: =RANK(C12,$C$5:$C$14) -> 7
A13: PT Mega Sparepart | B13: =COUNTIF(Kunci_Jawaban!C:C,A13) -> 20 | C13: =SUMIF(Kunci_Jawaban!C:C,A13,Kunci_Jawaban!L:L) -> 2109155000 | D13: =AVERAGEIF(Kunci_Jawaban!C:C,A13,Kunci_Jawaban!J:J) -> 7.75 | E13: =COUNTIFS(Kunci_Jawaban!C:C,A13,Kunci_Jawaban!I:I,"Received") -> 10 | F13: =COUNTIFS(Kunci_Jawaban!C:C,A13,Kunci_Jawaban!N:N,"Tepat Waktu") -> 1 | G13: =IFERROR(F13/E13*100,0) -> 10 | H13: =RANK(C13,$C$5:$C$14) -> 6
A14: PT Sumber Makmur | B14: =COUNTIF(Kunci_Jawaban!C:C,A14) -> 24 | C14: =SUMIF(Kunci_Jawaban!C:C,A14,Kunci_Jawaban!L:L) -> 2365750000 | D14: =AVERAGEIF(Kunci_Jawaban!C:C,A14,Kunci_Jawaban!J:J) -> 8 | E14: =COUNTIFS(Kunci_Jawaban!C:C,A14,Kunci_Jawaban!I:I,"Received") -> 15 | F14: =COUNTIFS(Kunci_Jawaban!C:C,A14,Kunci_Jawaban!N:N,"Tepat Waktu") -> 4 | G14: =IFERROR(F14/E14*100,0) -> 26.666667 | H14: =RANK(C14,$C$5:$C$14) -> 4
A16: TOTAL SELURUH PO | B16: =SUM(B5:B14) -> 230 | C16: =SUM(C5:C14) -> 19542010000

Sheet Panduan_Rumus
A1: Kolom / Tugas | B1: Rumus & Cara Kerja | C1: Untuk apa skill ini di dunia kerja / bullet CV
A2: Total Harga | B2: Rumus: Qty x Harga Satuan | C2: Dasar semua laporan pembelian - nilai transaksi per PO.
A3: Keterlambatan (hari) | B3: Rumus: IF(Status="Received",(TglTerima-TglPO)-LeadTimeJanji,"-") | C3: Menghitung selisih realisasi vs janji supplier - dipakai untuk evaluasi kinerja supplier (vendor scorecard).
A4: Status Ketepatan Kirim | B4: Rumus: IF(Status="Received",IF(Keterlambatan<=0,"Tepat Waktu","Terlambat"),"-") | C4: Klasifikasi otomatis ketepatan pengiriman, dasar KPI purchasing.
A5: Rekap per Supplier | B5: Rumus: COUNTIF, SUMIF, AVERAGEIF, COUNTIFS, RANK, IFERROR | C5: Membuat vendor performance report - total belanja per supplier, % ketepatan kirim, dan ranking supplier terbaik.
A6: RANK | B6: Rumus: RANK(nilai, range_nilai) | C6: Meranking supplier berdasarkan total nilai pembelian - berguna untuk negosiasi kontrak & evaluasi tahunan.
A7: IFERROR | B7: Rumus: IFERROR(rumus, nilai_jika_error) | C7: Mencegah tampilan pesan error pembagian dengan nol saat supplier belum ada PO Received - praktik profesional agar laporan rapi.
A9: Tips CV / Portofolio | B9: Cantumkan sebagai project: Menyusun sistem rekap purchasing 230 PO dari 10 supplier menggunakan Excel (SUMIF, COUNTIFS, RANK, IFERROR) untuk memantau ketepatan kirim & nilai pembelian per vendor. | C9: Boleh ditambahkan estimasi dampak realistis, misal: 'mempermudah identifikan supplier bermasalah dari waktu manual berjam-jam menjadi hitungan menit', selama dijelaskan sebagai simulasi/latihan mandiri.

Sheet Latihan_Lookup
A1: LATIHAN LOOKUP: VLOOKUP, INDEX+MATCH, HLOOKUP
A2: Data PO diambil dari sheet Kunci_Jawaban. Isi kolom kuning sendiri di baris 4 dst (baris 3 = contoh).
A4: Tabel Referensi 1: Lead Time Standar per Kategori Barang (untuk VLOOKUP & INDEX+MATCH)
A5: Kategori | B5: Kode Kategori | C5: Lead Time Standar (hari)
A6: ATK | B6: KTG01 | C6: 10
A7: Bahan Baku | B7: KTG02 | C7: 14
A8: Bahan Kemasan | B8: KTG03 | C8: 10
A9: Bahan Kimia | B9: KTG04 | C9: 10
A10: Consumables | B10: KTG05 | C10: 14
A11: Sparepart Mesin | B11: KTG06 | C11: 14
A14: Tabel Referensi 2: Persentase Diskon berdasarkan Tier Qty Pembelian (untuk HLOOKUP)
A15: Tier Qty | B15: 0-50 | C15: 51-150 | D15: 151-300 | E15: 301+
A16: % Diskon | B16: 0 | C16: 0.02 | D16: 0.05 | E16: 0.08
A19: Area Praktik (data dari sheet Kunci_Jawaban)
A20: No PO | B20: Supplier | C20: Kategori | D20: Qty | E20: Lead Time Standar (VLOOKUP) | F20: Lead Time Standar (INDEX+MATCH, cek silang) | G20: Tier Qty (bantuan) | H20: % Diskon (HLOOKUP)
A21: =Kunci_Jawaban!A2 -> PO-2024-0001 | B21: =Kunci_Jawaban!C2 -> PT Indo Chemical | C21: =Kunci_Jawaban!F2 -> Bahan Baku | D21: =Kunci_Jawaban!G2 -> 78 | E21: =VLOOKUP(C21,$A$6:$C$11,3,FALSE()) -> 14 | F21: =INDEX($C$6:$C$11,MATCH(C21,$A$6:$A$11,0)) -> 14 | G21: =IF(D21<=50,"0-50",IF(D21<=150,"51-150",IF(D21<=300,"151-300","301+"))) -> 51-150 | H21: =HLOOKUP(G21,$B$15:$E$16,2,FALSE()) -> 0.02
A22: =Kunci_Jawaban!A3 -> PO-2024-0002 | B22: =Kunci_Jawaban!C3 -> PT Mega Sparepart | C22: =Kunci_Jawaban!F3 -> Sparepart Mesin | D22: =Kunci_Jawaban!G3 -> 439
A23: =Kunci_Jawaban!A4 -> PO-2024-0003 | B23: =Kunci_Jawaban!C4 -> CV Anugrah Teknik | C23: =Kunci_Jawaban!F4 -> Consumables | D23: =Kunci_Jawaban!G4 -> 357
A24: =Kunci_Jawaban!A5 -> PO-2024-0004 | B24: =Kunci_Jawaban!C5 -> CV Anugrah Teknik | C24: =Kunci_Jawaban!F5 -> Sparepart Mesin | D24: =Kunci_Jawaban!G5 -> 314
A25: =Kunci_Jawaban!A6 -> PO-2024-0005 | B25: =Kunci_Jawaban!C6 -> PT Karya Abadi | C25: =Kunci_Jawaban!F6 -> ATK | D25: =Kunci_Jawaban!G6 -> 187
A26: =Kunci_Jawaban!A7 -> PO-2024-0006 | B26: =Kunci_Jawaban!C7 -> PT Mega Sparepart | C26: =Kunci_Jawaban!F7 -> Consumables | D26: =Kunci_Jawaban!G7 -> 400
A27: =Kunci_Jawaban!A8 -> PO-2024-0007 | B27: =Kunci_Jawaban!C8 -> PT Karya Abadi | C27: =Kunci_Jawaban!F8 -> Sparepart Mesin | D27: =Kunci_Jawaban!G8 -> 406
A28: =Kunci_Jawaban!A9 -> PO-2024-0008 | B28: =Kunci_Jawaban!C9 -> CV Sentosa Jaya | C28: =Kunci_Jawaban!F9 -> Bahan Baku | D28: =Kunci_Jawaban!G9 -> 232
A29: =Kunci_Jawaban!A10 -> PO-2024-0009 | B29: =Kunci_Jawaban!C10 -> CV Sentosa Jaya | C29: =Kunci_Jawaban!F10 -> Sparepart Mesin | D29: =Kunci_Jawaban!G10 -> 290
A30: =Kunci_Jawaban!A11 -> PO-2024-0010 | B30: =Kunci_Jawaban!C11 -> PT Indo Chemical | C30: =Kunci_Jawaban!F11 -> Bahan Kimia | D30: =Kunci_Jawaban!G11 -> 311
A31: =Kunci_Jawaban!A12 -> PO-2024-0011 | B31: =Kunci_Jawaban!C12 -> CV Anugrah Teknik | C31: =Kunci_Jawaban!F12 -> ATK | D31: =Kunci_Jawaban!G12 -> 466
A32: =Kunci_Jawaban!A13 -> PO-2024-0012 | B32: =Kunci_Jawaban!C13 -> CV Sinar Terang | C32: =Kunci_Jawaban!F13 -> Sparepart Mesin | D32: =Kunci_Jawaban!G13 -> 76
A33: =Kunci_Jawaban!A14 -> PO-2024-0013 | B33: =Kunci_Jawaban!C14 -> PT Baja Perkasa | C33: =Kunci_Jawaban!F14 -> ATK | D33: =Kunci_Jawaban!G14 -> 158
... A50: =Kunci_Jawaban!A31 -> PO-2024-0030 | B50: =Kunci_Jawaban!C31 -> CV Anugrah Teknik | C50: =Kunci_Jawaban!F31 -> ATK | D50: =Kunci_Jawaban!G31 -> 212
A53: Catatan: XLOOKUP sengaja tidak dipakai sebagai rumus hidup di file ini karena engine yang memverifikasi file ini belum bisa menghitungnya (berisiko rumus rusak/tidak terbaca saat dibuka). INDEX+MATCH di kolom F adalah pengganti XLOOKUP yang hasilnya identik dan didukung semua versi Excel/Google Sheets. Kalau Excel/Google Sheets kamu sudah versi baru, boleh dicoba sendiri (ketik manual): XLOOKUP(C3,A6:A11,C6:C11) — hasilnya akan sama dengan kolom E & F.
