Workbook

Sheet Data_Mentah
A1: Tanggal | B1: Kode Barang | C1: Nama Barang | D1: Kategori | E1: Satuan | F1: Jenis Transaksi | G1: Qty | H1: Harga Beli/Unit (khusus Masuk) | I1: Gudang
A2: 2024-01-03 | B2: BB-001 | C2: Plat Baja 2mm | D2: Bahan Baku | E2: Kg | F2: Masuk | G2: 193 | H2: 18716 | I2: Gudang Utama
A3: 2024-01-07 | B3: BB-001 | C3: Plat Baja 2mm | D3: Bahan Baku | E3: Kg | F3: Keluar | G3: 55 | I3: Gudang Utama
A4: 2024-01-10 | B4: BB-001 | C4: Plat Baja 2mm | D4: Bahan Baku | E4: Kg | F4: Keluar | G4: 23 | I4: Gudang Utama
A5: 2024-01-12 | B5: BB-001 | C5: Plat Baja 2mm | D5: Bahan Baku | E5: Kg | F5: Keluar | G5: 20 | I5: Gudang Utama
A6: 2024-01-15 | B6: BB-001 | C6: Plat Baja 2mm | D6: Bahan Baku | E6: Kg | F6: Keluar | G6: 27 | I6: Gudang Utama
A7: 2024-01-20 | B7: BB-001 | C7: Plat Baja 2mm | D7: Bahan Baku | E7: Kg | F7: Masuk | G7: 180 | H7: 16626 | I7: Gudang Utama
A8: 2024-01-26 | B8: BB-001 | C8: Plat Baja 2mm | D8: Bahan Baku | E8: Kg | F8: Masuk | G8: 24 | H8: 20154 | I8: Gudang Utama
A9: 2024-02-01 | B9: BB-001 | C9: Plat Baja 2mm | D9: Bahan Baku | E9: Kg | F9: Masuk | G9: 168 | H9: 20742 | I9: Gudang Utama
A10: 2024-02-05 | B10: BB-001 | C10: Plat Baja 2mm | D10: Bahan Baku | E10: Kg | F10: Keluar | G10: 37 | I10: Gudang Utama
A11: 2024-02-06 | B11: BB-001 | C11: Plat Baja 2mm | D11: Bahan Baku | E11: Kg | F11: Keluar | G11: 79 | I11: Gudang Utama
A12: 2024-02-11 | B12: BB-001 | C12: Plat Baja 2mm | D12: Bahan Baku | E12: Kg | F12: Keluar | G12: 109 | I12: Gudang Utama
A13: 2024-02-13 | B13: BB-001 | C13: Plat Baja 2mm | D13: Bahan Baku | E13: Kg | F13: Masuk | G13: 77 | H13: 20830 | I13: Gudang Utama
A14: 2024-02-19 | B14: BB-001 | C14: Plat Baja 2mm | D14: Bahan Baku | E14: Kg | F14: Keluar | G14: 27 | I14: Gudang Utama
A15: 2024-02-23 | B15: BB-001 | C15: Plat Baja 2mm | D15: Bahan Baku | E15: Kg | F15: Keluar | G15: 21 | I15: Gudang Utama
A16: 2024-02-27 | B16: BB-001 | C16: Plat Baja 2mm | D16: Bahan Baku | E16: Kg | F16: Masuk | G16: 22 | H16: 17956 | I16: Gudang Utama
A17: 2024-03-03 | B17: BB-001 | C17: Plat Baja 2mm | D17: Bahan Baku | E17: Kg | F17: Keluar | G17: 106 | I17: Gudang Utama
A18: 2024-03-08 | B18: BB-001 | C18: Plat Baja 2mm | D18: Bahan Baku | E18: Kg | F18: Masuk | G18: 60 | H18: 17467 | I18: Gudang Utama
A19: 2024-03-13 | B19: BB-001 | C19: Plat Baja 2mm | D19: Bahan Baku | E19: Kg | F19: Keluar | G19: 94 | I19: Gudang Utama
A20: 2024-03-15 | B20: BB-001 | C20: Plat Baja 2mm | D20: Bahan Baku | E20: Kg | F20: Keluar | G20: 71 | I20: Gudang Utama
A21: 2024-03-18 | B21: BB-001 | C21: Plat Baja 2mm | D21: Bahan Baku | E21: Kg | F21: Masuk | G21: 144 | H21: 17898 | I21: Gudang Utama
A22: 2024-03-19 | B22: BB-001 | C22: Plat Baja 2mm | D22: Bahan Baku | E22: Kg | F22: Masuk | G22: 79 | H22: 16350 | I22: Gudang Utama
A23: 2024-03-25 | B23: BB-001 | C23: Plat Baja 2mm | D23: Bahan Baku | E23: Kg | F23: Masuk | G23: 112 | H23: 19179 | I23: Gudang Utama
A24: 2024-03-29 | B24: BB-001 | C24: Plat Baja 2mm | D24: Bahan Baku | E24: Kg | F24: Keluar | G24: 15 | I24: Gudang Utama
A25: 2024-03-30 | B25: BB-001 | C25: Plat Baja 2mm | D25: Bahan Baku | E25: Kg | F25: Keluar | G25: 51 | I25: Gudang Utama
A26: 2024-03-31 | B26: BB-001 | C26: Plat Baja 2mm | D26: Bahan Baku | E26: Kg | F26: Keluar | G26: 76 | I26: Gudang Utama
A27: 2024-04-06 | B27: BB-001 | C27: Plat Baja 2mm | D27: Bahan Baku | E27: Kg | F27: Keluar | G27: 116 | I27: Gudang Utama
A28: 2024-04-12 | B28: BB-001 | C28: Plat Baja 2mm | D28: Bahan Baku | E28: Kg | F28: Masuk | G28: 159 | H28: 20670 | I28: Gudang Utama
A29: 2024-04-14 | B29: BB-001 | C29: Plat Baja 2mm | D29: Bahan Baku | E29: Kg | F29: Masuk | G29: 116 | H29: 18992 | I29: Gudang Utama
A30: 2024-04-19 | B30: BB-001 | C30: Plat Baja 2mm | D30: Bahan Baku | E30: Kg | F30: Keluar | G30: 116 | I30: Gudang Utama
A31: 2024-04-20 | B31: BB-001 | C31: Plat Baja 2mm | D31: Bahan Baku | E31: Kg | F31: Keluar | G31: 58 | I31: Gudang Utama
A32: 2024-04-22 | B32: BB-001 | C32: Plat Baja 2mm | D32: Bahan Baku | E32: Kg | F32: Keluar | G32: 55 | I32: Gudang Utama
A33: 2024-04-25 | B33: BB-001 | C33: Plat Baja 2mm | D33: Bahan Baku | E33: Kg | F33: Keluar | G33: 71 | I33: Gudang Utama
A34: 2024-04-30 | B34: BB-001 | C34: Plat Baja 2mm | D34: Bahan Baku | E34: Kg | F34: Masuk | G34: 55 | H34: 19603 | I34: Gudang Utama
A35: 2024-05-02 | B35: BB-001 | C35: Plat Baja 2mm | D35: Bahan Baku | E35: Kg | F35: Masuk | G35: 151 | H35: 18300 | I35: Gudang Utama
A36: 2024-05-04 | B36: BB-001 | C36: Plat Baja 2mm | D36: Bahan Baku | E36: Kg | F36: Masuk | G36: 60 | H36: 18967 | I36: Gudang Utama
A37: 2024-05-09 | B37: BB-001 | C37: Plat Baja 2mm | D37: Bahan Baku | E37: Kg | F37: Keluar | G37: 25 | I37: Gudang Utama
A38: 2024-05-15 | B38: BB-001 | C38: Plat Baja 2mm | D38: Bahan Baku | E38: Kg | F38: Masuk | G38: 104 | H38: 16928 | I38: Gudang Utama
A39: 2024-05-19 | B39: BB-001 | C39: Plat Baja 2mm | D39: Bahan Baku | E39: Kg | F39: Keluar | G39: 71 | I39: Gudang Utama
A40: 2024-05-21 | B40: BB-001 | C40: Plat Baja 2mm | D40: Bahan Baku | E40: Kg | F40: Keluar | G40: 92 | I40: Gudang Utama
...

Sheet Latihan_Isi_Sendiri
A1: Tanggal | B1: Kode Barang | C1: Nama Barang | D1: Kategori | E1: Satuan | F1: Jenis Transaksi | G1: Qty | H1: Harga Beli/Unit (khusus Masuk) | I1: Gudang | J1: Saldo Stok Berjalan (Qty) | K1: Sisa Qty Layer Ini (per Tgl Laporan) | L1: Nilai Sisa Persediaan FIFO (Rp) | N1: Tanggal Laporan (acuan) >> | O1: 2024-12-31
A2: 2024-01-03 | B2: BB-001 | C2: Plat Baja 2mm | D2: Bahan Baku | E2: Kg | F2: Masuk | G2: 193 | H2: 18716 | I2: Gudang Utama | J2: =SUMIFS($G$2:G2,$B$2:B2,B2,$F$2:F2,"Masuk")-SUMIFS($G$2:G2,$B$2:B2,B2,$F$2:F2,"Keluar") -> 193 | K2: =IF(F2="Masuk",MAX(0,MIN(G2,SUMIFS($G$2:G2,$B$2:B2,B2,$F$2:F2,"Masuk")-SUMIFS($G$2:G2,$B$2:B2,B2,$F$2:F2,"Keluar"))),"") -> 193 | L2: =IF(F2="Masuk",K2*H2,"") -> 3612188
A3: 2024-01-07 | B3: BB-001 | C3: Plat Baja 2mm | D3: Bahan Baku | E3: Kg | F3: Keluar | G3: 55 | I3: Gudang Utama
A4: 2024-01-10 | B4: BB-001 | C4: Plat Baja 2mm | D4: Bahan Baku | E4: Kg | F4: Keluar | G4: 23 | I4: Gudang Utama
A5: 2024-01-12 | B5: BB-001 | C5: Plat Baja 2mm | D5: Bahan Baku | E5: Kg | F5: Keluar | G5: 20 | I5: Gudang Utama
A6: 2024-01-15 | B6: BB-001 | C6: Plat Baja 2mm | D6: Bahan Baku | E6: Kg | F6: Keluar | G6: 27 | I6: Gudang Utama
A7: 2024-01-20 | B7: BB-001 | C7: Plat Baja 2mm | D7: Bahan Baku | E7: Kg | F7: Masuk | G7: 180 | H7: 16626 | I7: Gudang Utama
A8: 2024-01-26 | B8: BB-001 | C8: Plat Baja 2mm | D8: Bahan Baku | E8: Kg | F8: Masuk | G8: 24 | H8: 20154 | I8: Gudang Utama
A9: 2024-02-01 | B9: BB-001 | C9: Plat Baja 2mm | D9: Bahan Baku | E9: Kg | F9: Masuk | G9: 168 | H9: 20742 | I9: Gudang Utama
A10: 2024-02-05 | B10: BB-001 | C10: Plat Baja 2mm | D10: Bahan Baku | E10: Kg | F10: Keluar | G10: 37 | I10: Gudang Utama
A11: 2024-02-06 | B11: BB-001 | C11: Plat Baja 2mm | D11: Bahan Baku | E11: Kg | F11: Keluar | G11: 79 | I11: Gudang Utama
A12: 2024-02-11 | B12: BB-001 | C12: Plat Baja 2mm | D12: Bahan Baku | E12: Kg | F12: Keluar | G12: 109 | I12: Gudang Utama
A13: 2024-02-13 | B13: BB-001 | C13: Plat Baja 2mm | D13: Bahan Baku | E13: Kg | F13: Masuk | G13: 77 | H13: 20830 | I13: Gudang Utama
A14: 2024-02-19 | B14: BB-001 | C14: Plat Baja 2mm | D14: Bahan Baku | E14: Kg | F14: Keluar | G14: 27 | I14: Gudang Utama
A15: 2024-02-23 | B15: BB-001 | C15: Plat Baja 2mm | D15: Bahan Baku | E15: Kg | F15: Keluar | G15: 21 | I15: Gudang Utama
A16: 2024-02-27 | B16: BB-001 | C16: Plat Baja 2mm | D16: Bahan Baku | E16: Kg | F16: Masuk | G16: 22 | H16: 17956 | I16: Gudang Utama
A17: 2024-03-03 | B17: BB-001 | C17: Plat Baja 2mm | D17: Bahan Baku | E17: Kg | F17: Keluar | G17: 106 | I17: Gudang Utama
A18: 2024-03-08 | B18: BB-001 | C18: Plat Baja 2mm | D18: Bahan Baku | E18: Kg | F18: Masuk | G18: 60 | H18: 17467 | I18: Gudang Utama
A19: 2024-03-13 | B19: BB-001 | C19: Plat Baja 2mm | D19: Bahan Baku | E19: Kg | F19: Keluar | G19: 94 | I19: Gudang Utama
A20: 2024-03-15 | B20: BB-001 | C20: Plat Baja 2mm | D20: Bahan Baku | E20: Kg | F20: Keluar | G20: 71 | I20: Gudang Utama
A21: 2024-03-18 | B21: BB-001 | C21: Plat Baja 2mm | D21: Bahan Baku | E21: Kg | F21: Masuk | G21: 144 | H21: 17898 | I21: Gudang Utama
A22: 2024-03-19 | B22: BB-001 | C22: Plat Baja 2mm | D22: Bahan Baku | E22: Kg | F22: Masuk | G22: 79 | H22: 16350 | I22: Gudang Utama
A23: 2024-03-25 | B23: BB-001 | C23: Plat Baja 2mm | D23: Bahan Baku | E23: Kg | F23: Masuk | G23: 112 | H23: 19179 | I23: Gudang Utama
A24: 2024-03-29 | B24: BB-001 | C24: Plat Baja 2mm | D24: Bahan Baku | E24: Kg | F24: Keluar | G24: 15 | I24: Gudang Utama
A25: 2024-03-30 | B25: BB-001 | C25: Plat Baja 2mm | D25: Bahan Baku | E25: Kg | F25: Keluar | G25: 51 | I25: Gudang Utama
A26: 2024-03-31 | B26: BB-001 | C26: Plat Baja 2mm | D26: Bahan Baku | E26: Kg | F26: Keluar | G26: 76 | I26: Gudang Utama
A27: 2024-04-06 | B27: BB-001 | C27: Plat Baja 2mm | D27: Bahan Baku | E27: Kg | F27: Keluar | G27: 116 | I27: Gudang Utama
A28: 2024-04-12 | B28: BB-001 | C28: Plat Baja 2mm | D28: Bahan Baku | E28: Kg | F28: Masuk | G28: 159 | H28: 20670 | I28: Gudang Utama
A29: 2024-04-14 | B29: BB-001 | C29: Plat Baja 2mm | D29: Bahan Baku | E29: Kg | F29: Masuk | G29: 116 | H29: 18992 | I29: Gudang Utama
A30: 2024-04-19 | B30: BB-001 | C30: Plat Baja 2mm | D30: Bahan Baku | E30: Kg | F30: Keluar | G30: 116 | I30: Gudang Utama
A31: 2024-04-20 | B31: BB-001 | C31: Plat Baja 2mm | D31: Bahan Baku | E31: Kg | F31: Keluar | G31: 58 | I31: Gudang Utama
A32: 2024-04-22 | B32: BB-001 | C32: Plat Baja 2mm | D32: Bahan Baku | E32: Kg | F32: Keluar | G32: 55 | I32: Gudang Utama
A33: 2024-04-25 | B33: BB-001 | C33: Plat Baja 2mm | D33: Bahan Baku | E33: Kg | F33: Keluar | G33: 71 | I33: Gudang Utama
A34: 2024-04-30 | B34: BB-001 | C34: Plat Baja 2mm | D34: Bahan Baku | E34: Kg | F34: Masuk | G34: 55 | H34: 19603 | I34: Gudang Utama
A35: 2024-05-02 | B35: BB-001 | C35: Plat Baja 2mm | D35: Bahan Baku | E35: Kg | F35: Masuk | G35: 151 | H35: 18300 | I35: Gudang Utama
A36: 2024-05-04 | B36: BB-001 | C36: Plat Baja 2mm | D36: Bahan Baku | E36: Kg | F36: Masuk | G36: 60 | H36: 18967 | I36: Gudang Utama
A37: 2024-05-09 | B37: BB-001 | C37: Plat Baja 2mm | D37: Bahan Baku | E37: Kg | F37: Keluar | G37: 25 | I37: Gudang Utama
A38: 2024-05-15 | B38: BB-001 | C38: Plat Baja 2mm | D38: Bahan Baku | E38: Kg | F38: Masuk | G38: 104 | H38: 16928 | I38: Gudang Utama
A39: 2024-05-19 | B39: BB-001 | C39: Plat Baja 2mm | D39: Bahan Baku | E39: Kg | F39: Keluar | G39: 71 | I39: Gudang Utama
A40: 2024-05-21 | B40: BB-001 | C40: Plat Baja 2mm | D40: Bahan Baku | E40: Kg | F40: Keluar | G40: 92 | I40: Gudang Utama
...

Sheet Kunci_Jawaban
A1: Tanggal | B1: Kode Barang | C1: Nama Barang | D1: Kategori | E1: Satuan | F1: Jenis Transaksi | G1: Qty | H1: Harga Beli/Unit (khusus Masuk) | I1: Gudang | J1: Saldo Stok Berjalan (Qty) | K1: Sisa Qty Layer Ini (per Tgl Laporan) | L1: Nilai Sisa Persediaan FIFO (Rp) | N1: Tanggal Laporan (acuan) >> | O1: 2024-12-31
A2: 2024-01-03 | B2: BB-001 | C2: Plat Baja 2mm | D2: Bahan Baku | E2: Kg | F2: Masuk | G2: 193 | H2: 18716 | I2: Gudang Utama | J2: =SUMIFS($G$2:G2,$B$2:B2,B2,$F$2:F2,"Masuk")-SUMIFS($G$2:G2,$B$2:B2,B2,$F$2:F2,"Keluar") -> 193 | K2: =IF(F2="Masuk",MAX(0,MIN(G2,SUMIFS($G$2:G2,$B$2:B2,B2,$F$2:F2,"Masuk")-SUMIFS($G$2:G2,$B$2:B2,B2,$F$2:F2,"Keluar"))),"") -> 193 | L2: =IF(F2="Masuk",K2*H2,"") -> 3612188
A3: 2024-01-07 | B3: BB-001 | C3: Plat Baja 2mm | D3: Bahan Baku | E3: Kg | F3: Keluar | G3: 55 | I3: Gudang Utama | J3: =SUMIFS($G$2:G3,$B$2:B3,B3,$F$2:F3,"Masuk")-SUMIFS($G$2:G3,$B$2:B3,B3,$F$2:F3,"Keluar") -> 138 | K3: =IF(F3="Masuk",MAX(0,MIN(G3,SUMIFS($G$2:G3,$B$2:B3,B3,$F$2:F3,"Masuk")-SUMIFS($G$2:G3,$B$2:B3,B3,$F$2:F3,"Keluar"))),"") | L3: =IF(F3="Masuk",K3*H3,"")
A4: 2024-01-10 | B4: BB-001 | C4: Plat Baja 2mm | D4: Bahan Baku | E4: Kg | F4: Keluar | G4: 23 | I4: Gudang Utama | J4: =SUMIFS($G$2:G4,$B$2:B4,B4,$F$2:F4,"Masuk")-SUMIFS($G$2:G4,$B$2:B4,B4,$F$2:F4,"Keluar") -> 115 | K4: =IF(F4="Masuk",MAX(0,MIN(G4,SUMIFS($G$2:G4,$B$2:B4,B4,$F$2:F4,"Masuk")-SUMIFS($G$2:G4,$B$2:B4,B4,$F$2:F4,"Keluar"))),"") | L4: =IF(F4="Masuk",K4*H4,"")
A5: 2024-01-12 | B5: BB-001 | C5: Plat Baja 2mm | D5: Bahan Baku | E5: Kg | F5: Keluar | G5: 20 | I5: Gudang Utama | J5: =SUMIFS($G$2:G5,$B$2:B5,B5,$F$2:F5,"Masuk")-SUMIFS($G$2:G5,$B$2:B5,B5,$F$2:F5,"Keluar") -> 95 | K5: =IF(F5="Masuk",MAX(0,MIN(G5,SUMIFS($G$2:G5,$B$2:B5,B5,$F$2:F5,"Masuk")-SUMIFS($G$2:G5,$B$2:B5,B5,$F$2:F5,"Keluar"))),"") | L5: =IF(F5="Masuk",K5*H5,"")
A6: 2024-01-15 | B6: BB-001 | C6: Plat Baja 2mm | D6: Bahan Baku | E6: Kg | F6: Keluar | G6: 27 | I6: Gudang Utama | J6: =SUMIFS($G$2:G6,$B$2:B6,B6,$F$2:F6,"Masuk")-SUMIFS($G$2:G6,$B$2:B6,B6,$F$2:F6,"Keluar") -> 68 | K6: =IF(F6="Masuk",MAX(0,MIN(G6,SUMIFS($G$2:G6,$B$2:B6,B6,$F$2:F6,"Masuk")-SUMIFS($G$2:G6,$B$2:B6,B6,$F$2:F6,"Keluar"))),"") | L6: =IF(F6="Masuk",K6*H6,"")
A7: 2024-01-20 | B7: BB-001 | C7: Plat Baja 2mm | D7: Bahan Baku | E7: Kg | F7: Masuk | G7: 180 | H7: 16626 | I7: Gudang Utama | J7: =SUMIFS($G$2:G7,$B$2:B7,B7,$F$2:F7,"Masuk")-SUMIFS($G$2:G7,$B$2:B7,B7,$F$2:F7,"Keluar") -> 248 | K7: =IF(F7="Masuk",MAX(0,MIN(G7,SUMIFS($G$2:G7,$B$2:B7,B7,$F$2:F7,"Masuk")-SUMIFS($G$2:G7,$B$2:B7,B7,$F$2:F7,"Keluar"))),"") -> 180 | L7: =IF(F7="Masuk",K7*H7,"") -> 2992680
A8: 2024-01-26 | B8: BB-001 | C8: Plat Baja 2mm | D8: Bahan Baku | E8: Kg | F8: Masuk | G8: 24 | H8: 20154 | I8: Gudang Utama | J8: =SUMIFS($G$2:G8,$B$2:B8,B8,$F$2:F8,"Masuk")-SUMIFS($G$2:G8,$B$2:B8,B8,$F$2:F8,"Keluar") -> 272 | K8: =IF(F8="Masuk",MAX(0,MIN(G8,SUMIFS($G$2:G8,$B$2:B8,B8,$F$2:F8,"Masuk")-SUMIFS($G$2:G8,$B$2:B8,B8,$F$2:F8,"Keluar"))),"") -> 24 | L8: =IF(F8="Masuk",K8*H8,"") -> 483696
A9: 2024-02-01 | B9: BB-001 | C9: Plat Baja 2mm | D9: Bahan Baku | E9: Kg | F9: Masuk | G9: 168 | H9: 20742 | I9: Gudang Utama | J9: =SUMIFS($G$2:G9,$B$2:B9,B9,$F$2:F9,"Masuk")-SUMIFS($G$2:G9,$B$2:B9,B9,$F$2:F9,"Keluar") -> 440 | K9: =IF(F9="Masuk",MAX(0,MIN(G9,SUMIFS($G$2:G9,$B$2:B9,B9,$F$2:F9,"Masuk")-SUMIFS($G$2:G9,$B$2:B9,B9,$F$2:F9,"Keluar"))),"") -> 168 | L9: =IF(F9="Masuk",K9*H9,"") -> 3484656
A10: 2024-02-05 | B10: BB-001 | C10: Plat Baja 2mm | D10: Bahan Baku | E10: Kg | F10: Keluar | G10: 37 | I10: Gudang Utama | J10: =SUMIFS($G$2:G10,$B$2:B10,B10,$F$2:F10,"Masuk")-SUMIFS($G$2:G10,$B$2:B10,B10,$F$2:F10,"Keluar") -> 403 | K10: =IF(F10="Masuk",MAX(0,MIN(G10,SUMIFS($G$2:G10,$B$2:B10,B10,$F$2:F10,"Masuk")-SUMIFS($G$2:G10,$B$2:B10,B10,$F$2:F10,"Keluar"))),"") | L10: =IF(F10="Masuk",K10*H10,"")
A11: 2024-02-06 | B11: BB-001 | C11: Plat Baja 2mm | D11: Bahan Baku | E11: Kg | F11: Keluar | G11: 79 | I11: Gudang Utama | J11: =SUMIFS($G$2:G11,$B$2:B11,B11,$F$2:F11,"Masuk")-SUMIFS($G$2:G11,$B$2:B11,B11,$F$2:F11,"Keluar") -> 324 | K11: =IF(F11="Masuk",MAX(0,MIN(G11,SUMIFS($G$2:G11,$B$2:B11,B11,$F$2:F11,"Masuk")-SUMIFS($G$2:G11,$B$2:B11,B11,$F$2:F11,"Keluar"))),"") | L11: =IF(F11="Masuk",K11*H11,"")
A12: 2024-02-11 | B12: BB-001 | C12: Plat Baja 2mm | D12: Bahan Baku | E12: Kg | F12: Keluar | G12: 109 | I12: Gudang Utama | J12: =SUMIFS($G$2:G12,$B$2:B12,B12,$F$2:F12,"Masuk")-SUMIFS($G$2:G12,$B$2:B12,B12,$F$2:F12,"Keluar") -> 215 | K12: =IF(F12="Masuk",MAX(0,MIN(G12,SUMIFS($G$2:G12,$B$2:B12,B12,$F$2:F12,"Masuk")-SUMIFS($G$2:G12,$B$2:B12,B12,$F$2:F12,"Keluar"))),"") | L12: =IF(F12="Masuk",K12*H12,"")
A13: 2024-02-13 | B13: BB-001 | C13: Plat Baja 2mm | D13: Bahan Baku | E13: Kg | F13: Masuk | G13: 77 | H13: 20830 | I13: Gudang Utama | J13: =SUMIFS($G$2:G13,$B$2:B13,B13,$F$2:F13,"Masuk")-SUMIFS($G$2:G13,$B$2:B13,B13,$F$2:F13,"Keluar") -> 292 | K13: =IF(F13="Masuk",MAX(0,MIN(G13,SUMIFS($G$2:G13,$B$2:B13,B13,$F$2:F13,"Masuk")-SUMIFS($G$2:G13,$B$2:B13,B13,$F$2:F13,"Keluar"))),"") -> 77 | L13: =IF(F13="Masuk",K13*H13,"") -> 1603910
A14: 2024-02-19 | B14: BB-001 | C14: Plat Baja 2mm | D14: Bahan Baku | E14: Kg | F14: Keluar | G14: 27 | I14: Gudang Utama | J14: =SUMIFS($G$2:G14,$B$2:B14,B14,$F$2:F14,"Masuk")-SUMIFS($G$2:G14,$B$2:B14,B14,$F$2:F14,"Keluar") -> 265 | K14: =IF(F14="Masuk",MAX(0,MIN(G14,SUMIFS($G$2:G14,$B$2:B14,B14,$F$2:F14,"Masuk")-SUMIFS($G$2:G14,$B$2:B14,B14,$F$2:F14,"Keluar"))),"") | L14: =IF(F14="Masuk",K14*H14,"")
A15: 2024-02-23 | B15: BB-001 | C15: Plat Baja 2mm | D15: Bahan Baku | E15: Kg | F15: Keluar | G15: 21 | I15: Gudang Utama | J15: =SUMIFS($G$2:G15,$B$2:B15,B15,$F$2:F15,"Masuk")-SUMIFS($G$2:G15,$B$2:B15,B15,$F$2:F15,"Keluar") -> 244 | K15: =IF(F15="Masuk",MAX(0,MIN(G15,SUMIFS($G$2:G15,$B$2:B15,B15,$F$2:F15,"Masuk")-SUMIFS($G$2:G15,$B$2:B15,B15,$F$2:F15,"Keluar"))),"") | L15: =IF(F15="Masuk",K15*H15,"")
A16: 2024-02-27 | B16: BB-001 | C16: Plat Baja 2mm | D16: Bahan Baku | E16: Kg | F16: Masuk | G16: 22 | H16: 17956 | I16: Gudang Utama | J16: =SUMIFS($G$2:G16,$B$2:B16,B16,$F$2:F16,"Masuk")-SUMIFS($G$2:G16,$B$2:B16,B16,$F$2:F16,"Keluar") -> 266 | K16: =IF(F16="Masuk",MAX(0,MIN(G16,SUMIFS($G$2:G16,$B$2:B16,B16,$F$2:F16,"Masuk")-SUMIFS($G$2:G16,$B$2:B16,B16,$F$2:F16,"Keluar"))),"") -> 22 | L16: =IF(F16="Masuk",K16*H16,"") -> 395032
A17: 2024-03-03 | B17: BB-001 | C17: Plat Baja 2mm | D17: Bahan Baku | E17: Kg | F17: Keluar | G17: 106 | I17: Gudang Utama | J17: =SUMIFS($G$2:G17,$B$2:B17,B17,$F$2:F17,"Masuk")-SUMIFS($G$2:G17,$B$2:B17,B17,$F$2:F17,"Keluar") -> 160 | K17: =IF(F17="Masuk",MAX(0,MIN(G17,SUMIFS($G$2:G17,$B$2:B17,B17,$F$2:F17,"Masuk")-SUMIFS($G$2:G17,$B$2:B17,B17,$F$2:F17,"Keluar"))),"") | L17: =IF(F17="Masuk",K17*H17,"")
A18: 2024-03-08 | B18: BB-001 | C18: Plat Baja 2mm | D18: Bahan Baku | E18: Kg | F18: Masuk | G18: 60 | H18: 17467 | I18: Gudang Utama | J18: =SUMIFS($G$2:G18,$B$2:B18,B18,$F$2:F18,"Masuk")-SUMIFS($G$2:G18,$B$2:B18,B18,$F$2:F18,"Keluar") -> 220 | K18: =IF(F18="Masuk",MAX(0,MIN(G18,SUMIFS($G$2:G18,$B$2:B18,B18,$F$2:F18,"Masuk")-SUMIFS($G$2:G18,$B$2:B18,B18,$F$2:F18,"Keluar"))),"") -> 60 | L18: =IF(F18="Masuk",K18*H18,"") -> 1048020
A19: 2024-03-13 | B19: BB-001 | C19: Plat Baja 2mm | D19: Bahan Baku | E19: Kg | F19: Keluar | G19: 94 | I19: Gudang Utama | J19: =SUMIFS($G$2:G19,$B$2:B19,B19,$F$2:F19,"Masuk")-SUMIFS($G$2:G19,$B$2:B19,B19,$F$2:F19,"Keluar") -> 126 | K19: =IF(F19="Masuk",MAX(0,MIN(G19,SUMIFS($G$2:G19,$B$2:B19,B19,$F$2:F19,"Masuk")-SUMIFS($G$2:G19,$B$2:B19,B19,$F$2:F19,"Keluar"))),"") | L19: =IF(F19="Masuk",K19*H19,"")
A20: 2024-03-15 | B20: BB-001 | C20: Plat Baja 2mm | D20: Bahan Baku | E20: Kg | F20: Keluar | G20: 71 | I20: Gudang Utama | J20: =SUMIFS($G$2:G20,$B$2:B20,B20,$F$2:F20,"Masuk")-SUMIFS($G$2:G20,$B$2:B20,B20,$F$2:F20,"Keluar") -> 55 | K20: =IF(F20="Masuk",MAX(0,MIN(G20,SUMIFS($G$2:G20,$B$2:B20,B20,$F$2:F20,"Masuk")-SUMIFS($G$2:G20,$B$2:B20,B20,$F$2:F20,"Keluar"))),"") | L20: =IF(F20="Masuk",K20*H20,"")
A21: 2024-03-18 | B21: BB-001 | C21: Plat Baja 2mm | D21: Bahan Baku | E21: Kg | F21: Masuk | G21: 144 | H21: 17898 | I21: Gudang Utama | J21: =SUMIFS($G$2:G21,$B$2:B21,B21,$F$2:F21,"Masuk")-SUMIFS($G$2:G21,$B$2:B21,B21,$F$2:F21,"Keluar") -> 199 | K21: =IF(F21="Masuk",MAX(0,MIN(G21,SUMIFS($G$2:G21,$B$2:B21,B21,$F$2:F21,"Masuk")-SUMIFS($G$2:G21,$B$2:B21,B21,$F$2:F21,"Keluar"))),"") -> 144 | L21: =IF(F21="Masuk",K21*H21,"") -> 2577312
A22: 2024-03-19 | B22: BB-001 | C22: Plat Baja 2mm | D22: Bahan Baku | E22: Kg | F22: Masuk | G22: 79 | H22: 16350 | I22: Gudang Utama | J22: =SUMIFS($G$2:G22,$B$2:B22,B22,$F$2:F22,"Masuk")-SUMIFS($G$2:G22,$B$2:B22,B22,$F$2:F22,"Keluar") -> 278 | K22: =IF(F22="Masuk",MAX(0,MIN(G22,SUMIFS($G$2:G22,$B$2:B22,B22,$F$2:F22,"Masuk")-SUMIFS($G$2:G22,$B$2:B22,B22,$F$2:F22,"Keluar"))),"") -> 79 | L22: =IF(F22="Masuk",K22*H22,"") -> 1291650
A23: 2024-03-25 | B23: BB-001 | C23: Plat Baja 2mm | D23: Bahan Baku | E23: Kg | F23: Masuk | G23: 112 | H23: 19179 | I23: Gudang Utama | J23: =SUMIFS($G$2:G23,$B$2:B23,B23,$F$2:F23,"Masuk")-SUMIFS($G$2:G23,$B$2:B23,B23,$F$2:F23,"Keluar") -> 390 | K23: =IF(F23="Masuk",MAX(0,MIN(G23,SUMIFS($G$2:G23,$B$2:B23,B23,$F$2:F23,"Masuk")-SUMIFS($G$2:G23,$B$2:B23,B23,$F$2:F23,"Keluar"))),"") -> 112 | L23: =IF(F23="Masuk",K23*H23,"") -> 2148048
A24: 2024-03-29 | B24: BB-001 | C24: Plat Baja 2mm | D24: Bahan Baku | E24: Kg | F24: Keluar | G24: 15 | I24: Gudang Utama | J24: =SUMIFS($G$2:G24,$B$2:B24,B24,$F$2:F24,"Masuk")-SUMIFS($G$2:G24,$B$2:B24,B24,$F$2:F24,"Keluar") -> 375 | K24: =IF(F24="Masuk",MAX(0,MIN(G24,SUMIFS($G$2:G24,$B$2:B24,B24,$F$2:F24,"Masuk")-SUMIFS($G$2:G24,$B$2:B24,B24,$F$2:F24,"Keluar"))),"") | L24: =IF(F24="Masuk",K24*H24,"")
A25: 2024-03-30 | B25: BB-001 | C25: Plat Baja 2mm | D25: Bahan Baku | E25: Kg | F25: Keluar | G25: 51 | I25: Gudang Utama | J25: =SUMIFS($G$2:G25,$B$2:B25,B25,$F$2:F25,"Masuk")-SUMIFS($G$2:G25,$B$2:B25,B25,$F$2:F25,"Keluar") -> 324 | K25: =IF(F25="Masuk",MAX(0,MIN(G25,SUMIFS($G$2:G25,$B$2:B25,B25,$F$2:F25,"Masuk")-SUMIFS($G$2:G25,$B$2:B25,B25,$F$2:F25,"Keluar"))),"") | L25: =IF(F25="Masuk",K25*H25,"")
A26: 2024-03-31 | B26: BB-001 | C26: Plat Baja 2mm | D26: Bahan Baku | E26: Kg | F26: Keluar | G26: 76 | I26: Gudang Utama | J26: =SUMIFS($G$2:G26,$B$2:B26,B26,$F$2:F26,"Masuk")-SUMIFS($G$2:G26,$B$2:B26,B26,$F$2:F26,"Keluar") -> 248 | K26: =IF(F26="Masuk",MAX(0,MIN(G26,SUMIFS($G$2:G26,$B$2:B26,B26,$F$2:F26,"Masuk")-SUMIFS($G$2:G26,$B$2:B26,B26,$F$2:F26,"Keluar"))),"") | L26: =IF(F26="Masuk",K26*H26,"")
A27: 2024-04-06 | B27: BB-001 | C27: Plat Baja 2mm | D27: Bahan Baku | E27: Kg | F27: Keluar | G27: 116 | I27: Gudang Utama | J27: =SUMIFS($G$2:G27,$B$2:B27,B27,$F$2:F27,"Masuk")-SUMIFS($G$2:G27,$B$2:B27,B27,$F$2:F27,"Keluar") -> 132 | K27: =IF(F27="Masuk",MAX(0,MIN(G27,SUMIFS($G$2:G27,$B$2:B27,B27,$F$2:F27,"Masuk")-SUMIFS($G$2:G27,$B$2:B27,B27,$F$2:F27,"Keluar"))),"") | L27: =IF(F27="Masuk",K27*H27,"")
A28: 2024-04-12 | B28: BB-001 | C28: Plat Baja 2mm | D28: Bahan Baku | E28: Kg | F28: Masuk | G28: 159 | H28: 20670 | I28: Gudang Utama | J28: =SUMIFS($G$2:G28,$B$2:B28,B28,$F$2:F28,"Masuk")-SUMIFS($G$2:G28,$B$2:B28,B28,$F$2:F28,"Keluar") -> 291 | K28: =IF(F28="Masuk",MAX(0,MIN(G28,SUMIFS($G$2:G28,$B$2:B28,B28,$F$2:F28,"Masuk")-SUMIFS($G$2:G28,$B$2:B28,B28,$F$2:F28,"Keluar"))),"") -> 159 | L28: =IF(F28="Masuk",K28*H28,"") -> 3286530
A29: 2024-04-14 | B29: BB-001 | C29: Plat Baja 2mm | D29: Bahan Baku | E29: Kg | F29: Masuk | G29: 116 | H29: 18992 | I29: Gudang Utama | J29: =SUMIFS($G$2:G29,$B$2:B29,B29,$F$2:F29,"Masuk")-SUMIFS($G$2:G29,$B$2:B29,B29,$F$2:F29,"Keluar") -> 407 | K29: =IF(F29="Masuk",MAX(0,MIN(G29,SUMIFS($G$2:G29,$B$2:B29,B29,$F$2:F29,"Masuk")-SUMIFS($G$2:G29,$B$2:B29,B29,$F$2:F29,"Keluar"))),"") -> 116 | L29: =IF(F29="Masuk",K29*H29,"") -> 2203072
A30: 2024-04-19 | B30: BB-001 | C30: Plat Baja 2mm | D30: Bahan Baku | E30: Kg | F30: Keluar | G30: 116 | I30: Gudang Utama | J30: =SUMIFS($G$2:G30,$B$2:B30,B30,$F$2:F30,"Masuk")-SUMIFS($G$2:G30,$B$2:B30,B30,$F$2:F30,"Keluar") -> 291 | K30: =IF(F30="Masuk",MAX(0,MIN(G30,SUMIFS($G$2:G30,$B$2:B30,B30,$F$2:F30,"Masuk")-SUMIFS($G$2:G30,$B$2:B30,B30,$F$2:F30,"Keluar"))),"") | L30: =IF(F30="Masuk",K30*H30,"")
A31: 2024-04-20 | B31: BB-001 | C31: Plat Baja 2mm | D31: Bahan Baku | E31: Kg | F31: Keluar | G31: 58 | I31: Gudang Utama | J31: =SUMIFS($G$2:G31,$B$2:B31,B31,$F$2:F31,"Masuk")-SUMIFS($G$2:G31,$B$2:B31,B31,$F$2:F31,"Keluar") -> 233 | K31: =IF(F31="Masuk",MAX(0,MIN(G31,SUMIFS($G$2:G31,$B$2:B31,B31,$F$2:F31,"Masuk")-SUMIFS($G$2:G31,$B$2:B31,B31,$F$2:F31,"Keluar"))),"") | L31: =IF(F31="Masuk",K31*H31,"")
A32: 2024-04-22 | B32: BB-001 | C32: Plat Baja 2mm | D32: Bahan Baku | E32: Kg | F32: Keluar | G32: 55 | I32: Gudang Utama | J32: =SUMIFS($G$2:G32,$B$2:B32,B32,$F$2:F32,"Masuk")-SUMIFS($G$2:G32,$B$2:B32,B32,$F$2:F32,"Keluar") -> 178 | K32: =IF(F32="Masuk",MAX(0,MIN(G32,SUMIFS($G$2:G32,$B$2:B32,B32,$F$2:F32,"Masuk")-SUMIFS($G$2:G32,$B$2:B32,B32,$F$2:F32,"Keluar"))),"") | L32: =IF(F32="Masuk",K32*H32,"")
A33: 2024-04-25 | B33: BB-001 | C33: Plat Baja 2mm | D33: Bahan Baku | E33: Kg | F33: Keluar | G33: 71 | I33: Gudang Utama | J33: =SUMIFS($G$2:G33,$B$2:B33,B33,$F$2:F33,"Masuk")-SUMIFS($G$2:G33,$B$2:B33,B33,$F$2:F33,"Keluar") -> 107 | K33: =IF(F33="Masuk",MAX(0,MIN(G33,SUMIFS($G$2:G33,$B$2:B33,B33,$F$2:F33,"Masuk")-SUMIFS($G$2:G33,$B$2:B33,B33,$F$2:F33,"Keluar"))),"") | L33: =IF(F33="Masuk",K33*H33,"")
A34: 2024-04-30 | B34: BB-001 | C34: Plat Baja 2mm | D34: Bahan Baku | E34: Kg | F34: Masuk | G34: 55 | H34: 19603 | I34: Gudang Utama | J34: =SUMIFS($G$2:G34,$B$2:B34,B34,$F$2:F34,"Masuk")-SUMIFS($G$2:G34,$B$2:B34,B34,$F$2:F34,"Keluar") -> 162 | K34: =IF(F34="Masuk",MAX(0,MIN(G34,SUMIFS($G$2:G34,$B$2:B34,B34,$F$2:F34,"Masuk")-SUMIFS($G$2:G34,$B$2:B34,B34,$F$2:F34,"Keluar"))),"") -> 55 | L34: =IF(F34="Masuk",K34*H34,"") -> 1078165
A35: 2024-05-02 | B35: BB-001 | C35: Plat Baja 2mm | D35: Bahan Baku | E35: Kg | F35: Masuk | G35: 151 | H35: 18300 | I35: Gudang Utama | J35: =SUMIFS($G$2:G35,$B$2:B35,B35,$F$2:F35,"Masuk")-SUMIFS($G$2:G35,$B$2:B35,B35,$F$2:F35,"Keluar") -> 313 | K35: =IF(F35="Masuk",MAX(0,MIN(G35,SUMIFS($G$2:G35,$B$2:B35,B35,$F$2:F35,"Masuk")-SUMIFS($G$2:G35,$B$2:B35,B35,$F$2:F35,"Keluar"))),"") -> 151 | L35: =IF(F35="Masuk",K35*H35,"") -> 2763300
A36: 2024-05-04 | B36: BB-001 | C36: Plat Baja 2mm | D36: Bahan Baku | E36: Kg | F36: Masuk | G36: 60 | H36: 18967 | I36: Gudang Utama | J36: =SUMIFS($G$2:G36,$B$2:B36,B36,$F$2:F36,"Masuk")-SUMIFS($G$2:G36,$B$2:B36,B36,$F$2:F36,"Keluar") -> 373 | K36: =IF(F36="Masuk",MAX(0,MIN(G36,SUMIFS($G$2:G36,$B$2:B36,B36,$F$2:F36,"Masuk")-SUMIFS($G$2:G36,$B$2:B36,B36,$F$2:F36,"Keluar"))),"") -> 60 | L36: =IF(F36="Masuk",K36*H36,"") -> 1138020
A37: 2024-05-09 | B37: BB-001 | C37: Plat Baja 2mm | D37: Bahan Baku | E37: Kg | F37: Keluar | G37: 25 | I37: Gudang Utama | J37: =SUMIFS($G$2:G37,$B$2:B37,B37,$F$2:F37,"Masuk")-SUMIFS($G$2:G37,$B$2:B37,B37,$F$2:F37,"Keluar") -> 348 | K37: =IF(F37="Masuk",MAX(0,MIN(G37,SUMIFS($G$2:G37,$B$2:B37,B37,$F$2:F37,"Masuk")-SUMIFS($G$2:G37,$B$2:B37,B37,$F$2:F37,"Keluar"))),"") | L37: =IF(F37="Masuk",K37*H37,"")
A38: 2024-05-15 | B38: BB-001 | C38: Plat Baja 2mm | D38: Bahan Baku | E38: Kg | F38: Masuk | G38: 104 | H38: 16928 | I38: Gudang Utama | J38: =SUMIFS($G$2:G38,$B$2:B38,B38,$F$2:F38,"Masuk")-SUMIFS($G$2:G38,$B$2:B38,B38,$F$2:F38,"Keluar") -> 452 | K38: =IF(F38="Masuk",MAX(0,MIN(G38,SUMIFS($G$2:G38,$B$2:B38,B38,$F$2:F38,"Masuk")-SUMIFS($G$2:G38,$B$2:B38,B38,$F$2:F38,"Keluar"))),"") -> 104 | L38: =IF(F38="Masuk",K38*H38,"") -> 1760512
A39: 2024-05-19 | B39: BB-001 | C39: Plat Baja 2mm | D39: Bahan Baku | E39: Kg | F39: Keluar | G39: 71 | I39: Gudang Utama | J39: =SUMIFS($G$2:G39,$B$2:B39,B39,$F$2:F39,"Masuk")-SUMIFS($G$2:G39,$B$2:B39,B39,$F$2:F39,"Keluar") -> 381 | K39: =IF(F39="Masuk",MAX(0,MIN(G39,SUMIFS($G$2:G39,$B$2:B39,B39,$F$2:F39,"Masuk")-SUMIFS($G$2:G39,$B$2:B39,B39,$F$2:F39,"Keluar"))),"") | L39: =IF(F39="Masuk",K39*H39,"")
A40: 2024-05-21 | B40: BB-001 | C40: Plat Baja 2mm | D40: Bahan Baku | E40: Kg | F40: Keluar | G40: 92 | I40: Gudang Utama | J40: =SUMIFS($G$2:G40,$B$2:B40,B40,$F$2:F40,"Masuk")-SUMIFS($G$2:G40,$B$2:B40,B40,$F$2:F40,"Keluar") -> 289 | K40: =IF(F40="Masuk",MAX(0,MIN(G40,SUMIFS($G$2:G40,$B$2:B40,B40,$F$2:F40,"Masuk")-SUMIFS($G$2:G40,$B$2:B40,B40,$F$2:F40,"Keluar"))),"") | L40: =IF(F40="Masuk",K40*H40,"")
...

Sheet Rekap_Ringkasan
A1: REKAP PERSEDIAAN (METODE FIFO) - PT MAJUJAYA MANUFAKTUR
A2: Sumber data: sheet Kunci_Jawaban -- Nilai persediaan akhir dihitung dengan metode FIFO (First In First Out)
A4: Kode Barang | B4: Nama Barang | C4: Total Qty Masuk | D4: Total Qty Keluar | E4: Saldo Akhir (Qty) | F4: Nilai Persediaan Akhir FIFO (Rp)
A5: BB-001 | B5: Plat Baja 2mm | C5: =SUMIFS(Kunci_Jawaban!G:G,Kunci_Jawaban!B:B,A5,Kunci_Jawaban!F:F,"Masuk") -> 1821 | D5: =SUMIFS(Kunci_Jawaban!G:G,Kunci_Jawaban!B:B,A5,Kunci_Jawaban!F:F,"Keluar") -> 1713 | E5: =C5-D5 -> 108 | F5: =SUMIF(Kunci_Jawaban!B:B,A5,Kunci_Jawaban!L:L) -> 33898012
A6: BB-002 | B6: Resin Polimer | C6: =SUMIFS(Kunci_Jawaban!G:G,Kunci_Jawaban!B:B,A6,Kunci_Jawaban!F:F,"Masuk") -> 2757 | D6: =SUMIFS(Kunci_Jawaban!G:G,Kunci_Jawaban!B:B,A6,Kunci_Jawaban!F:F,"Keluar") -> 1663 | E6: =C6-D6 -> 1094 | F6: =SUMIF(Kunci_Jawaban!B:B,A6,Kunci_Jawaban!L:L) -> 70652695
A7: CH-001 | B7: Cat Epoxy | C7: =SUMIFS(Kunci_Jawaban!G:G,Kunci_Jawaban!B:B,A7,Kunci_Jawaban!F:F,"Masuk") -> 3076 | D7: =SUMIFS(Kunci_Jawaban!G:G,Kunci_Jawaban!B:B,A7,Kunci_Jawaban!F:F,"Keluar") -> 1369 | E7: =C7-D7 -> 1707 | F7: =SUMIF(Kunci_Jawaban!B:B,A7,Kunci_Jawaban!L:L) -> 78567456
A8: KM-001 | B8: Kardus Box L | C8: =SUMIFS(Kunci_Jawaban!G:G,Kunci_Jawaban!B:B,A8,Kunci_Jawaban!F:F,"Masuk") -> 2129 | D8: =SUMIFS(Kunci_Jawaban!G:G,Kunci_Jawaban!B:B,A8,Kunci_Jawaban!F:F,"Keluar") -> 1545 | E8: =C8-D8 -> 584 | F8: =SUMIF(Kunci_Jawaban!B:B,A8,Kunci_Jawaban!L:L) -> 38992846
A9: SP-001 | B9: Bearing 6205 | C9: =SUMIFS(Kunci_Jawaban!G:G,Kunci_Jawaban!B:B,A9,Kunci_Jawaban!F:F,"Masuk") -> 2271 | D9: =SUMIFS(Kunci_Jawaban!G:G,Kunci_Jawaban!B:B,A9,Kunci_Jawaban!F:F,"Keluar") -> 1665 | E9: =C9-D9 -> 606 | F9: =SUMIF(Kunci_Jawaban!B:B,A9,Kunci_Jawaban!L:L) -> 28830744
B10: TOTAL NILAI PERSEDIAAN AKHIR | F10: =SUM(F5:F9) -> 250941753

Sheet Panduan_Rumus
A1: Kolom / Tugas | B1: Rumus & Cara Kerja | C1: Untuk apa skill ini di dunia kerja / bullet CV
A2: Konsep dasar | B2: Data sudah diurutkan per Kode Barang lalu Tanggal (wajib untuk metode FIFO manual di Excel). Setiap barang masuk dianggap 'lapisan/layer' stok dengan harga belinya sendiri; saat barang keluar, yang dianggap terjual/terpakai adalah lapisan TERLAMA lebih dulu (First In First Out). | C2: Ini konsep akuntansi persediaan yang umum dipakai staff admin gudang & finance di perusahaan manufacturing.
A3: Saldo Stok Berjalan | B3: Rumus: SUMIFS(qty s.d. baris ini,kode=kode ini,jenis="Masuk") - SUMIFS(qty s.d. baris ini,kode=kode ini,jenis="Keluar") | C3: Kartu stok berjalan (running balance) - dasar laporan mutasi stok harian/bulanan.
A4: Sisa Qty Layer Ini | B4: Rumus: jika baris ini Masuk -> MAX(0, MIN(Qty layer, TotalMasukSampaiBarisIni - TotalKeluarSampaiBarisIni)); jika Keluar -> kosong | C4: Menghitung berapa unit dari SETIAP batch pembelian yang masih tersisa sampai tanggal laporan - inti dari metode FIFO.
A5: Nilai Sisa Persediaan FIFO | B5: Rumus: Sisa Qty Layer x Harga Beli per Unit layer tsb | C5: Nilai uang persediaan akhir sesuai standar akuntansi FIFO - dibutuhkan untuk laporan keuangan / stock opname.
A6: Rekap per Barang | B6: Rumus: SUMIFS (total masuk/keluar), SUMIF (total nilai FIFO) | C6: Membuat laporan nilai persediaan akhir per SKU - laporan yang nyaris selalu diminta ke admin gudang/inventory control setiap akhir bulan.
A8: Tips CV / Portofolio | B8: Cantumkan sebagai project: Menyusun kartu stok & valuasi persediaan akhir metode FIFO untuk 5 SKU (235 transaksi keluar-masuk) menggunakan Excel formula SUMIFS bertingkat, tanpa bantuan software ERP. | C8: Ini termasuk skill yang jarang dimiliki fresh graduate non-akuntansi - cocok dipakai membedakan diri Anda saat melamar admin gudang/purchasing/inventory.

Sheet Latihan_Lookup
A1: LATIHAN LOOKUP: VLOOKUP, INDEX+MATCH, HLOOKUP
A2: Data transaksi diambil dari sheet Kunci_Jawaban. Isi kolom kuning sendiri di baris 4 dst (baris 3 = contoh).
A4: Tabel Referensi 1: Master Barang & Minimum Stok (untuk VLOOKUP & INDEX+MATCH)
A5: Kode Barang | B5: Nama Barang | C5: Minimum Stok (Qty)
A6: BB-001 | B6: Plat Baja 2mm | C6: 100
A7: BB-002 | B7: Resin Polimer | C7: 100
A8: CH-001 | B8: Cat Epoxy | C8: 80
A9: KM-001 | B9: Kardus Box L | C9: 80
A10: SP-001 | B10: Bearing 6205 | C10: 80
A13: Tabel Referensi 2: Rekomendasi Aksi berdasarkan Level Status Stok (untuk HLOOKUP)
A14: Level | B14: Kritis | C14: Waspada | D14: Aman
A15: Rekomendasi Aksi | B15: Segera PO Ulang | C15: Pantau Ketat | D15: Tidak Perlu Aksi
A18: Area Praktik (data dari sheet Rekap_Ringkasan)
A19: Kode Barang | B19: Saldo Akhir (Qty) | C19: Nama Barang (VLOOKUP) | D19: Minimum Stok (INDEX+MATCH, cek silang) | E19: Level Status (bantuan) | F19: Rekomendasi Aksi (HLOOKUP)
A20: =Rekap_Ringkasan!A6 -> BB-002 | B20: =Rekap_Ringkasan!E6 -> 1094 | C20: =VLOOKUP(A20,$A$6:$C$10,2,FALSE()) -> Resin Polimer | D20: =INDEX($C$6:$C$10,MATCH(A20,$A$6:$A$10,0)) -> 100 | E20: =IF(B20<D20,"Kritis",IF(B20<D20*1.5,"Waspada","Aman")) -> Aman | F20: =HLOOKUP(E20,$B$14:$D$15,2,FALSE()) -> Tidak Perlu Aksi
A21: =Rekap_Ringkasan!A7 -> CH-001 | B21: =Rekap_Ringkasan!E7 -> 1707
A22: =Rekap_Ringkasan!A8 -> KM-001 | B22: =Rekap_Ringkasan!E8 -> 584
A23: =Rekap_Ringkasan!A9 -> SP-001 | B23: =Rekap_Ringkasan!E9 -> 606
A24: =Rekap_Ringkasan!A10 -> 0 | B24: =Rekap_Ringkasan!E10 -> 0
A27: Catatan: XLOOKUP sengaja tidak dipakai sebagai rumus hidup di file ini karena engine yang memverifikasi file ini belum bisa menghitungnya (berisiko rumus rusak/tidak terbaca saat dibuka). INDEX+MATCH di kolom D adalah pengganti XLOOKUP yang hasilnya identik dan didukung semua versi Excel/Google Sheets. Kalau Excel/Google Sheets kamu sudah versi baru, boleh dicoba sendiri (ketik manual): XLOOKUP(A21,A6:A10,C6:C10) — hasilnya akan sama dengan kolom C & D.
